Workbook

Sheet autozliczanie (2025-12)
B1: Tytuł | E1: RAZEM | H1: Histmag (szacunkowy) | K1: sieci | N1: Virtualo | Q1: Empik | T1: Publio | W1: Legimi | Z1: Nexto | AC1: Woblink | AF1: Azymut | AI1: Ebookpoint | AL1: Nasbi | AO1: Storytel | AR1: Audioteka | AU1: Bookbeat
H2: kwoty są szacunkowe
A4: 9788365156365 | B4: Azja we krwi, Konflikty – zbrodnie – ludobójstwo | E4: =H4+K4 -> 1 | F4: =I4+L4 -> 1.95 | H4: =SUMIF(konwertery!A$2:A$300,A4,Histmag!C$2:C$300) -> 0 | I4: =SUMIF(konwertery!A$2:A$300,A4,konwertery!B$2:B$300) * 0.97 -> 0 | K4: =N4+Q4+T4+W4+Z4+AC4+AF4+AI4+AL4+AO4+AR4+AU4 -> 1 | L4: =O4+R4+U4+X4+AA4+AD4+AG4+AJ4+AM4+AP4+AS4+AV4 -> 1.95 | N4: =SUMIF(konwertery!C$2:C$300,A4,Virtualo!L$2:L$300) -> 0 | O4: =(SUMIF(konwertery!C$2:C$300,A4,Virtualo!P$2:P$300)) -> 0 | Q4: =SUMIF(konwertery!D$2:D$300,A4,Empik!M$2:M$300) -> 0 | R4: =SUMIF(konwertery!D$2:D$300,A4,Empik!N$2:N$300) -> 0 | T4: =SUMIF(konwertery!E$2:E$300,A4,Publio!P$2:P$300) -> 0 | U4: =SUMIF(konwertery!E$2:E$300,A4,konwertery!F$2:F$300) -> 0 | W4: =SUMIF(Legimi!D$2:D$300,A4,Legimi!G$2:G$300) -> 0 | X4: =SUMIF(Legimi!D$2:D$300,A4,Legimi!H$2:H$300) -> 0 | Z4: =SUMIF(konwertery!G$2:G$302,A4,Nexto!J$2:J$283) -> 0 | AA4: =SUMIF(konwertery!G$2:G$302,A4,Nexto!N$2:P$302) -> 0 | AC4: =SUMIF(Woblink!E$14:E$314,A4,Woblink!I$14:I$314) -> 0 | AD4: =SUMIF(Woblink!E$14:E$314,A4,konwertery!R$2:R$300) -> 0 | AF4: =SUM(SUMIF(konwertery!I$2:I$300,A4,Azymut!H$2:H$298),(SUMIF(konwertery!S$2:S$300,A4,AzymutB!H$2:H300)*2)) -> 0 | AG4: =SUM(SUMIF(konwertery!I$2:I$300,A4,konwertery!J$2:J$300),SUMIF(konwertery!S$2:S$300,A4,konwertery!T$2:T$300)) -> 0 | AI4: =SUMIF(konwertery!K$2:K$300,A4,Ebookpoint!F$14:F$312) -> 0 | AJ4: =SUMIF(konwertery!K$2:K$300,A4,Ebookpoint!M$14:M$312) -> 0 | AL4: =SUMIF(konwertery!L$2:L$300,A4,Nasbi!F$14:F$312) -> 0 | AM4: =SUMIF(konwertery!L$2:L$300,A4,Nasbi!K$14:K$312) -> 0 | AO4: =SUMIF(StorytelE!C$2:C$300,A4,konwertery!M$2:M$300)+SUMIF(StorytelA!C$2:C$300,A4,konwertery!N$2:N$300) -> 1 | AP4: =SUMIF(StorytelE!C$2:C$300,A4,konwertery!O$2:O$300)+SUMIF(StorytelA!C$2:C$300,A4,konwertery!P$2:P$300) -> 1.95 | AR4: =SUMIF(konwertery!U$2:U$300,A4,Audioteka!E$4:E$302) -> 0 | AS4: =SUMIF(konwertery!U$2:U$300,A4,Audioteka!O$4:O$302) -> 0 | AU4: =SUMIF(Bookbeat!A$9:A$309,A4,Bookbeat!H$9:H$309) -> 0 | AV4: =SUMIF(Bookbeat!A$9:A$309,A4,Bookbeat!L$9:L$309) -> 0
A5: 9788393463077 | B5: Batoh 1652 – Wiedeń 1683, Od kompromitacji do wiktorii | E5: =H5+K5 -> 3 | F5: =I5+L5 -> 21.4952 | H5: =SUMIF(konwertery!A$2:A$300,A5,Histmag!C$2:C$300) -> 3 | I5: =SUMIF(konwertery!A$2:A$300,A5,konwertery!B$2:B$300) * 0.97 -> 21.4952 | K5: =N5+Q5+T5+W5+Z5+AC5+AF5+AI5+AL5+AO5+AR5+AU5 -> 0 | L5: =O5+R5+U5+X5+AA5+AD5+AG5+AJ5+AM5+AP5+AS5+AV5 -> 0 | N5: =SUMIF(konwertery!C$2:C$300,A5,Virtualo!L$2:L$300) -> 0 | O5: =(SUMIF(konwertery!C$2:C$300,A5,Virtualo!P$2:P$300)) -> 0 | Q5: =SUMIF(konwertery!D$2:D$300,A5,Empik!M$2:M$300) -> 0 | R5: =SUMIF(konwertery!D$2:D$300,A5,Empik!N$2:N$300) -> 0 | T5: =SUMIF(konwertery!E$2:E$300,A5,Publio!P$2:P$300) -> 0 | U5: =SUMIF(konwertery!E$2:E$300,A5,konwertery!F$2:F$300) -> 0 | W5: =SUMIF(Legimi!D$2:D$300,A5,Legimi!G$2:G$300) -> 0 | X5: =SUMIF(Legimi!D$2:D$300,A5,Legimi!H$2:H$300) -> 0 | Z5: =SUMIF(konwertery!G$2:G$302,A5,Nexto!J$2:J$283) -> 0 | AA5: =SUMIF(konwertery!G$2:G$302,A5,Nexto!N$2:P$302) -> 0 | AC5: =SUMIF(Woblink!E$9:E$309,A5,Woblink!I$9:I$309) -> 0 | AD5: =SUMIF(Woblink!E$14:E$314,A5,konwertery!R$2:R$300) -> 0 | AF5: =SUM(SUMIF(konwertery!I$2:I$300,A5,Azymut!H$2:H$298),(SUMIF(konwertery!S$2:S$300,A5,AzymutB!H$2:H301)*2)) -> 0 | AG5: =SUM(SUMIF(konwertery!I$2:I$300,A5,konwertery!J$2:J$300),SUMIF(konwertery!S$2:S$300,A5,konwertery!T$2:T$300)) -> 0 | AI5: =SUMIF(konwertery!K$2:K$300,A5,Ebookpoint!F$14:F$312) -> 0 | AJ5: =SUMIF(konwertery!K$2:K$300,A5,Ebookpoint!M$14:M$312) -> 0 | AL5: =SUMIF(konwertery!L$2:L$300,A5,Nasbi!F$14:F$312) -> 0 | AM5: =SUMIF(konwertery!L$2:L$300,A5,Nasbi!K$14:K$312) -> 0 | AO5: =SUMIF(StorytelE!C$2:C$300,A5,konwertery!M$2:M$300)+SUMIF(StorytelA!C$2:C$300,A5,konwertery!N$2:N$300) -> 0 | AP5: =SUMIF(StorytelE!C$2:C$300,A5,konwertery!O$2:O$300)+SUMIF(StorytelA!C$2:C$300,A5,konwertery!P$2:P$300) -> 0 | AR5: =SUMIF(konwertery!U$2:U$300,A5,Audioteka!E$4:E$302) -> 0 | AS5: =SUMIF(konwertery!U$2:U$300,A5,Audioteka!O$4:O$302) -> 0 | AU5: =SUMIF(Bookbeat!A$9:A$309,A5,Bookbeat!H$9:H$309) -> 0 | AV5: =SUMIF(Bookbeat!A$9:A$309,A5,Bookbeat!L$9:L$309) -> 0
A6: 9788365156068 | B6: Bohaterowie popkultury: od Robin Hooda do Rambo | E6: =H6+K6 -> 0 | F6: =I6+L6 -> 0 | H6: =SUMIF(konwertery!A$2:A$300,A6,Histmag!C$2:C$300) -> 0 | I6: =SUMIF(konwertery!A$2:A$300,A6,konwertery!B$2:B$300) * 0.97 -> 0 | K6: =N6+Q6+T6+W6+Z6+AC6+AF6+AI6+AL6+AO6+AR6+AU6 -> 0 | L6: =O6+R6+U6+X6+AA6+AD6+AG6+AJ6+AM6+AP6+AS6+AV6 -> 0 | N6: =SUMIF(konwertery!C$2:C$300,A6,Virtualo!L$2:L$300) -> 0 | O6: =(SUMIF(konwertery!C$2:C$300,A6,Virtualo!P$2:P$300)) -> 0 | Q6: =SUMIF(konwertery!D$2:D$300,A6,Empik!M$2:M$300) -> 0 | R6: =SUMIF(konwertery!D$2:D$300,A6,Empik!N$2:N$300) -> 0 | T6: =SUMIF(konwertery!E$2:E$300,A6,Publio!P$2:P$300) -> 0 | U6: =SUMIF(konwertery!E$2:E$300,A6,konwertery!F$2:F$300) -> 0 | W6: =SUMIF(Legimi!D$2:D$300,A6,Legimi!G$2:G$300) -> 0 | X6: =SUMIF(Legimi!D$2:D$300,A6,Legimi!H$2:H$300) -> 0 | Z6: =SUMIF(konwertery!G$2:G$302,A6,Nexto!J$2:J$283) -> 0 | AA6: =SUMIF(konwertery!G$2:G$302,A6,Nexto!N$2:P$302) -> 0 | AC6: =SUMIF(Woblink!E$9:E$309,A6,Woblink!I$9:I$309) -> 0 | AD6: =SUMIF(Woblink!E$14:E$314,A6,konwertery!R$2:R$300) -> 0 | AF6: =SUM(SUMIF(konwertery!I$2:I$300,A6,Azymut!H$2:H$298),(SUMIF(konwertery!S$2:S$300,A6,AzymutB!H$2:H302)*2)) -> 0 | AG6: =SUM(SUMIF(konwertery!I$2:I$300,A6,konwertery!J$2:J$300),SUMIF(konwertery!S$2:S$300,A6,konwertery!T$2:T$300)) -> 0 | AI6: =SUMIF(konwertery!K$2:K$300,A6,Ebookpoint!F$14:F$312) -> 0 | AJ6: =SUMIF(konwertery!K$2:K$300,A6,Ebookpoint!M$14:M$312) -> 0 | AL6: =SUMIF(konwertery!L$2:L$300,A6,Nasbi!F$14:F$312) -> 0 | AM6: =SUMIF(konwertery!L$2:L$300,A6,Nasbi!K$14:K$312) -> 0 | AO6: =SUMIF(StorytelE!C$2:C$300,A6,konwertery!M$2:M$300)+SUMIF(StorytelA!C$2:C$300,A6,konwertery!N$2:N$300) -> 0 | AP6: =SUMIF(StorytelE!C$2:C$300,A6,konwertery!O$2:O$300)+SUMIF(StorytelA!C$2:C$300,A6,konwertery!P$2:P$300) -> 0 | AR6: =SUMIF(konwertery!U$2:U$300,A6,Audioteka!E$4:E$302) -> 0 | AS6: =SUMIF(konwertery!U$2:U$300,A6,Audioteka!O$4:O$302) -> 0 | AU6: =SUMIF(Bookbeat!A$9:A$309,A6,Bookbeat!H$9:H$309) -> 0 | AV6: =SUMIF(Bookbeat!A$9:A$309,A6,Bookbeat!L$9:L$309) -> 0
A7: 9788365156754 | B7: Cywilizacja śmierci. Rosyjski kolonializm na Wschodzie | E7: =H7+K7 -> 6 | F7: =I7+L7 -> 60.2103 | H7: =SUMIF(konwertery!A$2:A$300,A7,Histmag!C$2:C$300) -> 3 | I7: =SUMIF(konwertery!A$2:A$300,A7,konwertery!B$2:B$300) * 0.97 -> 32.9703 | K7: =N7+Q7+T7+W7+Z7+AC7+AF7+AI7+AL7+AO7+AR7+AU7 -> 3 | L7: =O7+R7+U7+X7+AA7+AD7+AG7+AJ7+AM7+AP7+AS7+AV7 -> 27.24 | N7: =SUMIF(konwertery!C$2:C$300,A7,Virtualo!L$2:L$300) -> 0 | O7: =(SUMIF(konwertery!C$2:C$300,A7,Virtualo!P$2:P$300)) -> 0 | Q7: =SUMIF(konwertery!D$2:D$300,A7,Empik!M$2:M$300) -> 0 | R7: =SUMIF(konwertery!D$2:D$300,A7,Empik!N$2:N$300) -> 0 | T7: =SUMIF(konwertery!E$2:E$300,A7,Publio!P$2:P$300) -> 0 | U7: =SUMIF(konwertery!E$2:E$300,A7,konwertery!F$2:F$300) -> 0 | W7: =SUMIF(Legimi!D$2:D$300,A7,Legimi!G$2:G$300) -> 0 | X7: =SUMIF(Legimi!D$2:D$300,A7,Legimi!H$2:H$300) -> 0 | Z7: =SUMIF(konwertery!G$2:G$302,A7,Nexto!J$2:J$283) -> 0 | AA7: =SUMIF(konwertery!G$2:G$302,A7,Nexto!N$2:P$302) -> 0 | AC7: =SUMIF(Woblink!E$14:E$314,A7,Woblink!I$14:I$314) -> 0 | AD7: =SUMIF(Woblink!E$14:E$314,A7,konwertery!R$2:R$300) -> 0 | AF7: =SUM(SUMIF(konwertery!I$2:I$300,A7,Azymut!H$2:H$298),(SUMIF(konwertery!S$2:S$300,A7,AzymutB!H$2:H303)*2)) -> 0 | AG7: =SUM(SUMIF(konwertery!I$2:I$300,A7,konwertery!J$2:J$300),SUMIF(konwertery!S$2:S$300,A7,konwertery!T$2:T$300)) -> 0 | AI7: =SUMIF(konwertery!K$2:K$300,A7,Ebookpoint!F$14:F$312) -> 3 | AJ7: =SUMIF(konwertery!K$2:K$300,A7,Ebookpoint!M$14:M$312) -> 27.24 | AL7: =SUMIF(konwertery!L$2:L$300,A7,Nasbi!F$14:F$312) -> 0 | AM7: =SUMIF(konwertery!L$2:L$300,A7,Nasbi!K$14:K$312) -> 0 | AO7: =SUMIF(StorytelE!C$2:C$300,A7,konwertery!M$2:M$300)+SUMIF(StorytelA!C$2:C$300,A7,konwertery!N$2:N$300) -> 0 | AP7: =SUMIF(StorytelE!C$2:C$300,A7,konwertery!O$2:O$300)+SUMIF(StorytelA!C$2:C$300,A7,konwertery!P$2:P$300) -> 0 | AR7: =SUMIF(konwertery!U$2:U$300,A7,Audioteka!E$4:E$302) -> 0 | AS7: =SUMIF(konwertery!U$2:U$300,A7,Audioteka!O$4:O$302) -> 0 | AU7: =SUMIF(Bookbeat!A$9:A$309,A7,Bookbeat!H$9:H$309) -> 0 | AV7: =SUMIF(Bookbeat!A$9:A$309,A7,Bookbeat!L$9:L$309) -> 0
A8: 9788365156808 | B8: Cywilizacja śmierci. Rosyjski kolonializm na Wschodzie (audio) | E8: =H8+K8 -> 75 | F8: =I8+L8 -> 113.45 | H8: =SUMIF(konwertery!A$2:A$300,A8,Histmag!C$2:C$300) -> 0 | I8: =SUMIF(konwertery!A$2:A$300,A8,konwertery!B$2:B$300) * 0.97 -> 0 | K8: =N8+Q8+T8+W8+Z8+AC8+AF8+AI8+AL8+AO8+AR8+AU8 -> 75 | L8: =O8+R8+U8+X8+AA8+AD8+AG8+AJ8+AM8+AP8+AS8+AV8 -> 113.45 | N8: =SUMIF(konwertery!C$2:C$300,A8,Virtualo!L$2:L$300) -> 0 | O8: =(SUMIF(konwertery!C$2:C$300,A8,Virtualo!P$2:P$300)) -> 0 | Q8: =SUMIF(konwertery!D$2:D$300,A8,Empik!M$2:M$300) -> 1 | R8: =SUMIF(konwertery!D$2:D$300,A8,Empik!N$2:N$300) -> 9 | T8: =SUMIF(konwertery!E$2:E$300,A8,Publio!P$2:P$300) -> 0 | U8: =SUMIF(konwertery!E$2:E$300,A8,konwertery!F$2:F$300) -> 0 | W8: =SUMIF(Legimi!D$2:D$300,A8,Legimi!G$2:G$300) -> 0 | X8: =SUMIF(Legimi!D$2:D$300,A8,Legimi!H$2:H$300) -> 0 | Z8: =SUMIF(konwertery!G$2:G$302,A8,Nexto!J$2:J$283) -> 0 | AA8: =SUMIF(konwertery!G$2:G$302,A8,Nexto!N$2:P$302) -> 0 | AC8: =SUMIF(Woblink!E$14:E$314,A8,Woblink!I$14:I$314) -> 0 | AD8: =SUMIF(Woblink!E$14:E$314,A8,konwertery!R$2:R$300) -> 0 | AF8: =SUM(SUMIF(konwertery!I$2:I$300,A8,Azymut!H$2:H$298),(SUMIF(konwertery!S$2:S$300,A8,AzymutB!H$2:H304)*2)) -> 0 | AG8: =SUM(SUMIF(konwertery!I$2:I$300,A8,konwertery!J$2:J$300),SUMIF(konwertery!S$2:S$300,A8,konwertery!T$2:T$300)) -> 0 | AI8: =SUMIF(konwertery!K$2:K$300,A8,Ebookpoint!F$14:F$312) -> 0 | AJ8: =SUMIF(konwertery!K$2:K$300,A8,Ebookpoint!M$14:M$312) -> 0 | AL8: =SUMIF(konwertery!L$2:L$300,A8,Nasbi!F$14:F$312) -> 0 | AM8: =SUMIF(konwertery!L$2:L$300,A8,Nasbi!K$14:K$312) -> 0 | AO8: =SUMIF(StorytelE!C$2:C$300,A8,konwertery!M$2:M$300)+SUMIF(StorytelA!C$2:C$300,A8,konwertery!N$2:N$300) -> 73 | AP8: =SUMIF(StorytelE!C$2:C$300,A8,konwertery!O$2:O$300)+SUMIF(StorytelA!C$2:C$300,A8,konwertery!P$2:P$300) -> 95.94 | AR8: =SUMIF(konwertery!U$2:U$300,A8,Audioteka!E$4:E$302) -> 1 | AS8: =SUMIF(konwertery!U$2:U$300,A8,Audioteka!O$4:O$302) -> 8.51 | AU8: =SUMIF(Bookbeat!A$9:A$309,A8,Bookbeat!H$9:H$309) -> 0 | AV8: =SUMIF(Bookbeat!A$9:A$309,A8,Bookbeat!L$9:L$309) -> 0
A9: 9788365156594 | B9: Czerwone mundury, Armia Brytyjska w czasach wojny o niepodległość USA | E9: =H9+K9 -> 1 | F9: =I9+L9 -> 5.9461 | H9: =SUMIF(konwertery!A$2:A$300,A9,Histmag!C$2:C$300) -> 1 | I9: =SUMIF(konwertery!A$2:A$300,A9,konwertery!B$2:B$300) * 0.97 -> 5.9461 | K9: =N9+Q9+T9+W9+Z9+AC9+AF9+AI9+AL9+AO9+AR9+AU9 -> 0 | L9: =O9+R9+U9+X9+AA9+AD9+AG9+AJ9+AM9+AP9+AS9+AV9 -> 0 | N9: =SUMIF(konwertery!C$2:C$300,A9,Virtualo!L$2:L$300) -> 0 | O9: =(SUMIF(konwertery!C$2:C$300,A9,Virtualo!P$2:P$300)) -> 0 | Q9: =SUMIF(konwertery!D$2:D$300,A9,Empik!M$2:M$300) -> 0 | R9: =SUMIF(konwertery!D$2:D$300,A9,Empik!N$2:N$300) -> 0 | T9: =SUMIF(konwertery!E$2:E$300,A9,Publio!P$2:P$300) -> 0 | U9: =SUMIF(konwertery!E$2:E$300,A9,konwertery!F$2:F$300) -> 0 | W9: =SUMIF(Legimi!D$2:D$300,A9,Legimi!G$2:G$300) -> 0 | X9: =SUMIF(Legimi!D$2:D$300,A9,Legimi!H$2:H$300) -> 0 | Z9: =SUMIF(konwertery!G$2:G$302,A9,Nexto!J$2:J$283) -> 0 | AA9: =SUMIF(konwertery!G$2:G$302,A9,Nexto!N$2:P$302) -> 0 | AC9: =SUMIF(Woblink!E$9:E$309,A9,Woblink!I$9:I$309) -> 0 | AD9: =SUMIF(Woblink!E$14:E$314,A9,konwertery!R$2:R$300) -> 0 | AF9: =SUM(SUMIF(konwertery!I$2:I$300,A9,Azymut!H$2:H$298),(SUMIF(konwertery!S$2:S$300,A9,AzymutB!H$2:H305)*2)) -> 0 | AG9: =SUM(SUMIF(konwertery!I$2:I$300,A9,konwertery!J$2:J$300),SUMIF(konwertery!S$2:S$300,A9,konwertery!T$2:T$300)) -> 0 | AI9: =SUMIF(konwertery!K$2:K$300,A9,Ebookpoint!F$14:F$312) -> 0 | AJ9: =SUMIF(konwertery!K$2:K$300,A9,Ebookpoint!M$14:M$312) -> 0 | AL9: =SUMIF(konwertery!L$2:L$300,A9,Nasbi!F$14:F$312) -> 0 | AM9: =SUMIF(konwertery!L$2:L$300,A9,Nasbi!K$14:K$312) -> 0 | AO9: =SUMIF(StorytelE!C$2:C$300,A9,konwertery!M$2:M$300)+SUMIF(StorytelA!C$2:C$300,A9,konwertery!N$2:N$300) -> 0 | AP9: =SUMIF(StorytelE!C$2:C$300,A9,konwertery!O$2:O$300)+SUMIF(StorytelA!C$2:C$300,A9,konwertery!P$2:P$300) -> 0 | AR9: =SUMIF(konwertery!U$2:U$300,A9,Audioteka!E$4:E$302) -> 0 | AS9: =SUMIF(konwertery!U$2:U$300,A9,Audioteka!O$4:O$302) -> 0 | AU9: =SUMIF(Bookbeat!A$9:A$309,A9,Bookbeat!H$9:H$309) -> 0 | AV9: =SUMIF(Bookbeat!A$9:A$309,A9,Bookbeat!L$9:L$309) -> 0
A10: 9788393463022 | B10: Czy Zygmunt III Waza zasłużył na niesławę? | E10: =H10+K10 -> 1 | F10: =I10+L10 -> 4.1516 | H10: =SUMIF(konwertery!A$2:A$300,A10,Histmag!C$2:C$300) -> 1 | I10: =SUMIF(konwertery!A$2:A$300,A10,konwertery!B$2:B$300) * 0.97 -> 4.1516 | K10: =N10+Q10+T10+W10+Z10+AC10+AF10+AI10+AL10+AO10+AR10+AU10 -> 0 | L10: =O10+R10+U10+X10+AA10+AD10+AG10+AJ10+AM10+AP10+AS10+AV10 -> 0 | N10: =SUMIF(konwertery!C$2:C$300,A10,Virtualo!L$2:L$300) -> 0 | O10: =(SUMIF(konwertery!C$2:C$300,A10,Virtualo!P$2:P$300)) -> 0 | Q10: =SUMIF(konwertery!D$2:D$300,A10,Empik!M$2:M$300) -> 0 | R10: =SUMIF(konwertery!D$2:D$300,A10,Empik!N$2:N$300) -> 0 | T10: =SUMIF(konwertery!E$2:E$300,A10,Publio!P$2:P$300) -> 0 | U10: =SUMIF(konwertery!E$2:E$300,A10,konwertery!F$2:F$300) -> 0 | W10: =SUMIF(Legimi!D$2:D$300,A10,Legimi!G$2:G$300) -> 0 | X10: =SUMIF(Legimi!D$2:D$300,A10,Legimi!H$2:H$300) -> 0 | Z10: =SUMIF(konwertery!G$2:G$302,A10,Nexto!J$2:J$283) -> 0 | AA10: =SUMIF(konwertery!G$2:G$302,A10,Nexto!N$2:P$302) -> 0 | AC10: =SUMIF(Woblink!E$9:E$309,A10,Woblink!I$9:I$309) -> 0 | AD10: =SUMIF(Woblink!E$14:E$314,A10,konwertery!R$2:R$300) -> 0 | AF10: =SUM(SUMIF(konwertery!I$2:I$300,A10,Azymut!H$2:H$298),(SUMIF(konwertery!S$2:S$300,A10,AzymutB!H$2:H306)*2)) -> 0 | AG10: =SUM(SUMIF(konwertery!I$2:I$300,A10,konwertery!J$2:J$300),SUMIF(konwertery!S$2:S$300,A10,konwertery!T$2:T$300)) -> 0 | AI10: =SUMIF(konwertery!K$2:K$300,A10,Ebookpoint!F$14:F$312) -> 0 | AJ10: =SUMIF(konwertery!K$2:K$300,A10,Ebookpoint!M$14:M$312) -> 0 | AL10: =SUMIF(konwertery!L$2:L$300,A10,Nasbi!F$14:F$312) -> 0 | AM10: =SUMIF(konwertery!L$2:L$300,A10,Nasbi!K$14:K$312) -> 0 | AO10: =SUMIF(StorytelE!C$2:C$300,A10,konwertery!M$2:M$300)+SUMIF(StorytelA!C$2:C$300,A10,konwertery!N$2:N$300) -> 0 | AP10: =SUMIF(StorytelE!C$2:C$300,A10,konwertery!O$2:O$300)+SUMIF(StorytelA!C$2:C$300,A10,konwertery!P$2:P$300) -> 0 | AR10: =SUMIF(konwertery!U$2:U$300,A10,Audioteka!E$4:E$302) -> 0 | AS10: =SUMIF(konwertery!U$2:U$300,A10,Audioteka!O$4:O$302) -> 0 | AU10: =SUMIF(Bookbeat!A$9:A$309,A10,Bookbeat!H$9:H$309) -> 0 | AV10: =SUMIF(Bookbeat!A$9:A$309,A10,Bookbeat!L$9:L$309) -> 0
A11: 9788365156044 | B11: Damy wielkiego ekranu: Gwiazdy Hollywood od Audrey Hepburn do Elizabeth Taylor | E11: =H11+K11 -> 0 | F11: =I11+L11 -> 0 | H11: =SUMIF(konwertery!A$2:A$300,A11,Histmag!C$2:C$300) -> 0 | I11: =SUMIF(konwertery!A$2:A$300,A11,konwertery!B$2:B$300) * 0.97 -> 0 | K11: =N11+Q11+T11+W11+Z11+AC11+AF11+AI11+AL11+AO11+AR11+AU11 -> 0 | L11: =O11+R11+U11+X11+AA11+AD11+AG11+AJ11+AM11+AP11+AS11+AV11 -> 0 | N11: =SUMIF(konwertery!C$2:C$300,A11,Virtualo!L$2:L$300) -> 0 | O11: =(SUMIF(konwertery!C$2:C$300,A11,Virtualo!P$2:P$300)) -> 0 | Q11: =SUMIF(konwertery!D$2:D$300,A11,Empik!M$2:M$300) -> 0 | R11: =SUMIF(konwertery!D$2:D$300,A11,Empik!N$2:N$300) -> 0 | T11: =SUMIF(konwertery!E$2:E$300,A11,Publio!P$2:P$300) -> 0 | U11: =SUMIF(konwertery!E$2:E$300,A11,konwertery!F$2:F$300) -> 0 | W11: =SUMIF(Legimi!D$2:D$300,A11,Legimi!G$2:G$300) -> 0 | X11: =SUMIF(Legimi!D$2:D$300,A11,Legimi!H$2:H$300) -> 0 | Z11: =SUMIF(konwertery!G$2:G$302,A11,Nexto!J$2:J$283) -> 0 | AA11: =SUMIF(konwertery!G$2:G$302,A11,Nexto!N$2:P$302) -> 0 | AC11: =SUMIF(Woblink!E$9:E$309,A11,Woblink!I$9:I$309) -> 0 | AD11: =SUMIF(Woblink!E$14:E$314,A11,konwertery!R$2:R$300) -> 0 | AF11: =SUM(SUMIF(konwertery!I$2:I$300,A11,Azymut!H$2:H$298),(SUMIF(konwertery!S$2:S$300,A11,AzymutB!H$2:H307)*2)) -> 0 | AG11: =SUM(SUMIF(konwertery!I$2:I$300,A11,konwertery!J$2:J$300),SUMIF(konwertery!S$2:S$300,A11,konwertery!T$2:T$300)) -> 0 | AI11: =SUMIF(konwertery!K$2:K$300,A11,Ebookpoint!F$14:F$312) -> 0 | AJ11: =SUMIF(konwertery!K$2:K$300,A11,Ebookpoint!M$14:M$312) -> 0 | AL11: =SUMIF(konwertery!L$2:L$300,A11,Nasbi!F$14:F$312) -> 0 | AM11: =SUMIF(konwertery!L$2:L$300,A11,Nasbi!K$14:K$312) -> 0 | AO11: =SUMIF(StorytelE!C$2:C$300,A11,konwertery!M$2:M$300)+SUMIF(StorytelA!C$2:C$300,A11,konwertery!N$2:N$300) -> 0 | AP11: =SUMIF(StorytelE!C$2:C$300,A11,konwertery!O$2:O$300)+SUMIF(StorytelA!C$2:C$300,A11,konwertery!P$2:P$300) -> 0 | AR11: =SUMIF(konwertery!U$2:U$300,A11,Audioteka!E$4:E$302) -> 0 | AS11: =SUMIF(konwertery!U$2:U$300,A11,Audioteka!O$4:O$302) -> 0 | AU11: =SUMIF(Bookbeat!A$9:A$309,A11,Bookbeat!H$9:H$309) -> 0 | AV11: =SUMIF(Bookbeat!A$9:A$309,A11,Bookbeat!L$9:L$309) -> 0
A12: 9788365156532 | B12: Dowody zbrodni, Początki kryminalistyki | E12: =H12+K12 -> 5 | F12: =I12+L12 -> 45.8262 | H12: =SUMIF(konwertery!A$2:A$300,A12,Histmag!C$2:C$300) -> 1 | I12: =SUMIF(konwertery!A$2:A$300,A12,konwertery!B$2:B$300) * 0.97 -> 10.1462 | K12: =N12+Q12+T12+W12+Z12+AC12+AF12+AI12+AL12+AO12+AR12+AU12 -> 4 | L12: =O12+R12+U12+X12+AA12+AD12+AG12+AJ12+AM12+AP12+AS12+AV12 -> 35.68 | N12: =SUMIF(konwertery!C$2:C$300,A12,Virtualo!L$2:L$300) -> 1 | O12: =(SUMIF(konwertery!C$2:C$300,A12,Virtualo!P$2:P$300)) -> 12.31 | Q12: =SUMIF(konwertery!D$2:D$300,A12,Empik!M$2:M$300) -> 2 | R12: =SUMIF(konwertery!D$2:D$300,A12,Empik!N$2:N$300) -> 12 | T12: =SUMIF(konwertery!E$2:E$300,A12,Publio!P$2:P$300) -> 0 | U12: =SUMIF(konwertery!E$2:E$300,A12,konwertery!F$2:F$300) -> 0 | W12: =SUMIF(Legimi!D$2:D$300,A12,Legimi!G$2:G$300) -> 0 | X12: =SUMIF(Legimi!D$2:D$300,A12,Legimi!H$2:H$300) -> 0 | Z12: =SUMIF(konwertery!G$2:G$302,A12,Nexto!J$2:J$283) -> 0 | AA12: =SUMIF(konwertery!G$2:G$302,A12,Nexto!N$2:P$302) -> 0 | AC12: =SUMIF(Woblink!E$9:E$309,A12,Woblink!I$9:I$309) -> 1 | AD12: =SUMIF(Woblink!E$14:E$314,A12,konwertery!R$2:R$300) -> 11.37 | AF12: =SUM(SUMIF(konwertery!I$2:I$300,A12,Azymut!H$2:H$298),(SUMIF(konwertery!S$2:S$300,A12,AzymutB!H$2:H308)*2)) -> 0 | AG12: =SUM(SUMIF(konwertery!I$2:I$300,A12,konwertery!J$2:J$300),SUMIF(konwertery!S$2:S$300,A12,konwertery!T$2:T$300)) -> 0 | AI12: =SUMIF(konwertery!K$2:K$300,A12,Ebookpoint!F$14:F$312) -> 0 | AJ12: =SUMIF(konwertery!K$2:K$300,A12,Ebookpoint!M$14:M$312) -> 0 | AL12: =SUMIF(konwertery!L$2:L$300,A12,Nasbi!F$14:F$312) -> 0 | AM12: =SUMIF(konwertery!L$2:L$300,A12,Nasbi!K$14:K$312) -> 0 | AO12: =SUMIF(StorytelE!C$2:C$300,A12,konwertery!M$2:M$300)+SUMIF(StorytelA!C$2:C$300,A12,konwertery!N$2:N$300) -> 0 | AP12: =SUMIF(StorytelE!C$2:C$300,A12,konwertery!O$2:O$300)+SUMIF(StorytelA!C$2:C$300,A12,konwertery!P$2:P$300) -> 0 | AR12: =SUMIF(konwertery!U$2:U$300,A12,Audioteka!E$4:E$302) -> 0 | AS12: =SUMIF(konwertery!U$2:U$300,A12,Audioteka!O$4:O$302) -> 0 | AU12: =SUMIF(Bookbeat!A$9:A$309,A12,Bookbeat!H$9:H$309) -> 0 | AV12: =SUMIF(Bookbeat!A$9:A$309,A12,Bookbeat!L$9:L$309) -> 0
A13: 9788365156624 | B13: Dowody zbrodni, Początki kryminalistyki (audio) | E13: =H13+K13 -> 6 | F13: =I13+L13 -> 42.79 | H13: =SUMIF(konwertery!A$2:A$300,A13,Histmag!C$2:C$300) -> 0 | I13: =SUMIF(konwertery!A$2:A$300,A13,konwertery!B$2:B$300) * 0.97 -> 0 | K13: =N13+Q13+T13+W13+Z13+AC13+AF13+AI13+AL13+AO13+AR13+AU13 -> 6 | L13: =O13+R13+U13+X13+AA13+AD13+AG13+AJ13+AM13+AP13+AS13+AV13 -> 42.79 | N13: =SUMIF(konwertery!C$2:C$300,A13,Virtualo!L$2:L$300) -> 0 | O13: =(SUMIF(konwertery!C$2:C$300,A13,Virtualo!P$2:P$300)) -> 0 | Q13: =SUMIF(konwertery!D$2:D$300,A13,Empik!M$2:M$300) -> 0 | R13: =SUMIF(konwertery!D$2:D$300,A13,Empik!N$2:N$300) -> 0 | T13: =SUMIF(konwertery!E$2:E$300,A13,Publio!P$2:P$300) -> 0 | U13: =SUMIF(konwertery!E$2:E$300,A13,konwertery!F$2:F$300) -> 0 | W13: =SUMIF(Legimi!D$2:D$300,A13,Legimi!G$2:G$300) -> 0 | X13: =SUMIF(Legimi!D$2:D$300,A13,Legimi!H$2:H$300) -> 0 | Z13: =SUMIF(konwertery!G$2:G$302,A13,Nexto!J$2:J$283) -> 0 | AA13: =SUMIF(konwertery!G$2:G$302,A13,Nexto!N$2:P$302) -> 0 | AC13: =SUMIF(Woblink!E$9:E$309,A13,Woblink!I$9:I$309) -> 0 | AD13: =SUMIF(Woblink!E$14:E$314,A13,konwertery!R$2:R$300) -> 0 | AF13: =SUM(SUMIF(konwertery!I$2:I$300,A13,Azymut!H$2:H$298),(SUMIF(konwertery!S$2:S$300,A13,AzymutB!H$2:H309)*2)) -> 1 | AG13: =SUM(SUMIF(konwertery!I$2:I$300,A13,konwertery!J$2:J$300),SUMIF(konwertery!S$2:S$300,A13,konwertery!T$2:T$300)) -> 11.37 | AI13: =SUMIF(konwertery!K$2:K$300,A13,Ebookpoint!F$14:F$312) -> 1 | AJ13: =SUMIF(konwertery!K$2:K$300,A13,Ebookpoint!M$14:M$312) -> 12.13 | AL13: =SUMIF(konwertery!L$2:L$300,A13,Nasbi!F$14:F$312) -> 1 | AM13: =SUMIF(konwertery!L$2:L$300,A13,Nasbi!K$14:K$312) -> 12.13 | AO13: =SUMIF(StorytelE!C$2:C$300,A13,konwertery!M$2:M$300)+SUMIF(StorytelA!C$2:C$300,A13,konwertery!N$2:N$300) -> 2 | AP13: =SUMIF(StorytelE!C$2:C$300,A13,konwertery!O$2:O$300)+SUMIF(StorytelA!C$2:C$300,A13,konwertery!P$2:P$300) -> 4.06 | AR13: =SUMIF(konwertery!U$2:U$300,A13,Audioteka!E$4:E$302) -> 0 | AS13: =SUMIF(konwertery!U$2:U$300,A13,Audioteka!O$4:O$302) -> 0 | AU13: =SUMIF(Bookbeat!A$9:A$309,A13,Bookbeat!H$9:H$309) -> 1 | AV13: =SUMIF(Bookbeat!A$9:A$309,A13,Bookbeat!L$9:L$309) -> 3.1
A14: 9788365156181 | B14: Dramat Afganistanu: XIX wiek | E14: =H14+K14 -> 0 | F14: =I14+L14 -> 0 | H14: =SUMIF(konwertery!A$2:A$300,A14,Histmag!C$2:C$300) -> 0 | I14: =SUMIF(konwertery!A$2:A$300,A14,konwertery!B$2:B$300) * 0.97 -> 0 | K14: =N14+Q14+T14+W14+Z14+AC14+AF14+AI14+AL14+AO14+AR14+AU14 -> 0 | L14: =O14+R14+U14+X14+AA14+AD14+AG14+AJ14+AM14+AP14+AS14+AV14 -> 0 | N14: =SUMIF(konwertery!C$2:C$300,A14,Virtualo!L$2:L$300) -> 0 | O14: =(SUMIF(konwertery!C$2:C$300,A14,Virtualo!P$2:P$300)) -> 0 | Q14: =SUMIF(konwertery!D$2:D$300,A14,Empik!M$2:M$300) -> 0 | R14: =SUMIF(konwertery!D$2:D$300,A14,Empik!N$2:N$300) -> 0 | T14: =SUMIF(konwertery!E$2:E$300,A14,Publio!P$2:P$300) -> 0 | U14: =SUMIF(konwertery!E$2:E$300,A14,konwertery!F$2:F$300) -> 0 | W14: =SUMIF(Legimi!D$2:D$300,A14,Legimi!G$2:G$300) -> 0 | X14: =SUMIF(Legimi!D$2:D$300,A14,Legimi!H$2:H$300) -> 0 | Z14: =SUMIF(konwertery!G$2:G$302,A14,Nexto!J$2:J$283) -> 0 | AA14: =SUMIF(konwertery!G$2:G$302,A14,Nexto!N$2:P$302) -> 0 | AC14: =SUMIF(Woblink!E$9:E$309,A14,Woblink!I$9:I$309) -> 0 | AD14: =SUMIF(Woblink!E$14:E$314,A14,konwertery!R$2:R$300) -> 0 | AF14: =SUM(SUMIF(konwertery!I$2:I$300,A14,Azymut!H$2:H$298),(SUMIF(konwertery!S$2:S$300,A14,AzymutB!H$2:H310)*2)) -> 0 | AG14: =SUM(SUMIF(konwertery!I$2:I$300,A14,konwertery!J$2:J$300),SUMIF(konwertery!S$2:S$300,A14,konwertery!T$2:T$300)) -> 0 | AI14: =SUMIF(konwertery!K$2:K$300,A14,Ebookpoint!F$14:F$312) -> 0 | AJ14: =SUMIF(konwertery!K$2:K$300,A14,Ebookpoint!M$14:M$312) -> 0 | AL14: =SUMIF(konwertery!L$2:L$300,A14,Nasbi!F$14:F$312) -> 0 | AM14: =SUMIF(konwertery!L$2:L$300,A14,Nasbi!K$14:K$312) -> 0 | AO14: =SUMIF(StorytelE!C$2:C$300,A14,konwertery!M$2:M$300)+SUMIF(StorytelA!C$2:C$300,A14,konwertery!N$2:N$300) -> 0 | AP14: =SUMIF(StorytelE!C$2:C$300,A14,konwertery!O$2:O$300)+SUMIF(StorytelA!C$2:C$300,A14,konwertery!P$2:P$300) -> 0 | AR14: =SUMIF(konwertery!U$2:U$300,A14,Audioteka!E$4:E$302) -> 0 | AS14: =SUMIF(konwertery!U$2:U$300,A14,Audioteka!O$4:O$302) -> 0 | AU14: =SUMIF(Bookbeat!A$9:A$309,A14,Bookbeat!H$9:H$309) -> 0 | AV14: =SUMIF(Bookbeat!A$9:A$309,A14,Bookbeat!L$9:L$309) -> 0
A15: 9788365156204 | B15: Dramat Afganistanu: XX wiek | E15: =H15+K15 -> 1 | F15: =I15+L15 -> 4.3 | H15: =SUMIF(konwertery!A$2:A$300,A15,Histmag!C$2:C$300) -> 0 | I15: =SUMIF(konwertery!A$2:A$300,A15,konwertery!B$2:B$300) * 0.97 -> 0 | K15: =N15+Q15+T15+W15+Z15+AC15+AF15+AI15+AL15+AO15+AR15+AU15 -> 1 | L15: =O15+R15+U15+X15+AA15+AD15+AG15+AJ15+AM15+AP15+AS15+AV15 -> 4.3 | N15: =SUMIF(konwertery!C$2:C$300,A15,Virtualo!L$2:L$300) -> 0 | O15: =(SUMIF(konwertery!C$2:C$300,A15,Virtualo!P$2:P$300)) -> 0 | Q15: =SUMIF(konwertery!D$2:D$300,A15,Empik!M$2:M$300) -> 0 | R15: =SUMIF(konwertery!D$2:D$300,A15,Empik!N$2:N$300) -> 0 | T15: =SUMIF(konwertery!E$2:E$300,A15,Publio!P$2:P$300) -> 0 | U15: =SUMIF(konwertery!E$2:E$300,A15,konwertery!F$2:F$300) -> 0 | W15: =SUMIF(Legimi!D$2:D$300,A15,Legimi!G$2:G$300) -> 0 | X15: =SUMIF(Legimi!D$2:D$300,A15,Legimi!H$2:H$300) -> 0 | Z15: =SUMIF(konwertery!G$2:G$302,A15,Nexto!J$2:J$283) -> 1 | AA15: =SUMIF(konwertery!G$2:G$302,A15,Nexto!N$2:P$302) -> 4.3 | AC15: =SUMIF(Woblink!E$9:E$309,A15,Woblink!I$9:I$309) -> 0 | AD15: =SUMIF(Woblink!E$14:E$314,A15,konwertery!R$2:R$300) -> 0 | AF15: =SUM(SUMIF(konwertery!I$2:I$300,A15,Azymut!H$2:H$298),(SUMIF(konwertery!S$2:S$300,A15,AzymutB!H$2:H311)*2)) -> 0 | AG15: =SUM(SUMIF(konwertery!I$2:I$300,A15,konwertery!J$2:J$300),SUMIF(konwertery!S$2:S$300,A15,konwertery!T$2:T$300)) -> 0 | AI15: =SUMIF(konwertery!K$2:K$300,A15,Ebookpoint!F$14:F$312) -> 0 | AJ15: =SUMIF(konwertery!K$2:K$300,A15,Ebookpoint!M$14:M$312) -> 0 | AL15: =SUMIF(konwertery!L$2:L$300,A15,Nasbi!F$14:F$312) -> 0 | AM15: =SUMIF(konwertery!L$2:L$300,A15,Nasbi!K$14:K$312) -> 0 | AO15: =SUMIF(StorytelE!C$2:C$300,A15,konwertery!M$2:M$300)+SUMIF(StorytelA!C$2:C$300,A15,konwertery!N$2:N$300) -> 0 | AP15: =SUMIF(StorytelE!C$2:C$300,A15,konwertery!O$2:O$300)+SUMIF(StorytelA!C$2:C$300,A15,konwertery!P$2:P$300) -> 0 | AR15: =SUMIF(konwertery!U$2:U$300,A15,Audioteka!E$4:E$302) -> 0 | AS15: =SUMIF(konwertery!U$2:U$300,A15,Audioteka!O$4:O$302) -> 0 | AU15: =SUMIF(Bookbeat!A$9:A$309,A15,Bookbeat!H$9:H$309) -> 0 | AV15: =SUMIF(Bookbeat!A$9:A$309,A15,Bookbeat!L$9:L$309) -> 0
A16: 9788365156631 | B16: Droga do imperium. Początki Wielkiej Brytanii 1603-1707 | E16: =H16+K16 -> 1 | F16: =I16+L16 -> 9.5448 | H16: =SUMIF(konwertery!A$2:A$300,A16,Histmag!C$2:C$300) -> 1 | I16: =SUMIF(konwertery!A$2:A$300,A16,konwertery!B$2:B$300) * 0.97 -> 9.5448 | K16: =N16+Q16+T16+W16+Z16+AC16+AF16+AI16+AL16+AO16+AR16+AU16 -> 0 | L16: =O16+R16+U16+X16+AA16+AD16+AG16+AJ16+AM16+AP16+AS16+AV16 -> 0 | N16: =SUMIF(konwertery!C$2:C$300,A16,Virtualo!L$2:L$300) -> 0 | O16: =(SUMIF(konwertery!C$2:C$300,A16,Virtualo!P$2:P$300)) -> 0 | Q16: =SUMIF(konwertery!D$2:D$300,A16,Empik!M$2:M$300) -> 0 | R16: =SUMIF(konwertery!D$2:D$300,A16,Empik!N$2:N$300) -> 0 | T16: =SUMIF(konwertery!E$2:E$300,A16,Publio!P$2:P$300) -> 0 | U16: =SUMIF(konwertery!E$2:E$300,A16,konwertery!F$2:F$300) -> 0 | W16: =SUMIF(Legimi!D$2:D$300,A16,Legimi!G$2:G$300) -> 0 | X16: =SUMIF(Legimi!D$2:D$300,A16,Legimi!H$2:H$300) -> 0 | Z16: =SUMIF(konwertery!G$2:G$302,A16,Nexto!J$2:J$283) -> 0 | AA16: =SUMIF(konwertery!G$2:G$302,A16,Nexto!N$2:P$302) -> 0 | AC16: =SUMIF(Woblink!E$9:E$309,A16,Woblink!I$9:I$309) -> 0 | AD16: =SUMIF(Woblink!E$14:E$314,A16,konwertery!R$2:R$300) -> 0 | AF16: =SUM(SUMIF(konwertery!I$2:I$300,A16,Azymut!H$2:H$298),(SUMIF(konwertery!S$2:S$300,A16,AzymutB!H$2:H312)*2)) -> 0 | AG16: =SUM(SUMIF(konwertery!I$2:I$300,A16,konwertery!J$2:J$300),SUMIF(konwertery!S$2:S$300,A16,konwertery!T$2:T$300)) -> 0 | AI16: =SUMIF(konwertery!K$2:K$300,A16,Ebookpoint!F$14:F$312) -> 0 | AJ16: =SUMIF(konwertery!K$2:K$300,A16,Ebookpoint!M$14:M$312) -> 0 | AL16: =SUMIF(konwertery!L$2:L$300,A16,Nasbi!F$14:F$312) -> 0 | AM16: =SUMIF(konwertery!L$2:L$300,A16,Nasbi!K$14:K$312) -> 0 | AO16: =SUMIF(StorytelE!C$2:C$300,A16,konwertery!M$2:M$300)+SUMIF(StorytelA!C$2:C$300,A16,konwertery!N$2:N$300) -> 0 | AP16: =SUMIF(StorytelE!C$2:C$300,A16,konwertery!O$2:O$300)+SUMIF(StorytelA!C$2:C$300,A16,konwertery!P$2:P$300) -> 0 | AR16: =SUMIF(konwertery!U$2:U$300,A16,Audioteka!E$4:E$302) -> 0 | AS16: =SUMIF(konwertery!U$2:U$300,A16,Audioteka!O$4:O$302) -> 0 | AU16: =SUMIF(Bookbeat!A$9:A$309,A16,Bookbeat!H$9:H$309) -> 0 | AV16: =SUMIF(Bookbeat!A$9:A$309,A16,Bookbeat!L$9:L$309) -> 0
A17: 9788393463084 | B17: Elita władzy w Królestwie Jerozolimskim | E17: =H17+K17 -> 0 | F17: =I17+L17 -> 0 | H17: =SUMIF(konwertery!A$2:A$300,A17,Histmag!C$2:C$300) -> 0 | I17: =SUMIF(konwertery!A$2:A$300,A17,konwertery!B$2:B$300) * 0.97 -> 0 | K17: =N17+Q17+T17+W17+Z17+AC17+AF17+AI17+AL17+AO17+AR17+AU17 -> 0 | L17: =O17+R17+U17+X17+AA17+AD17+AG17+AJ17+AM17+AP17+AS17+AV17 -> 0 | N17: =SUMIF(konwertery!C$2:C$300,A17,Virtualo!L$2:L$300) -> 0 | O17: =(SUMIF(konwertery!C$2:C$300,A17,Virtualo!P$2:P$300)) -> 0 | Q17: =SUMIF(konwertery!D$2:D$300,A17,Empik!M$2:M$300) -> 0 | R17: =SUMIF(konwertery!D$2:D$300,A17,Empik!N$2:N$300) -> 0 | T17: =SUMIF(konwertery!E$2:E$300,A17,Publio!P$2:P$300) -> 0 | U17: =SUMIF(konwertery!E$2:E$300,A17,konwertery!F$2:F$300) -> 0 | W17: =SUMIF(Legimi!D$2:D$300,A17,Legimi!G$2:G$300) -> 0 | X17: =SUMIF(Legimi!D$2:D$300,A17,Legimi!H$2:H$300) -> 0 | Z17: =SUMIF(konwertery!G$2:G$302,A17,Nexto!J$2:J$283) -> 0 | AA17: =SUMIF(konwertery!G$2:G$302,A17,Nexto!N$2:P$302) -> 0 | AC17: =SUMIF(Woblink!E$9:E$309,A17,Woblink!I$9:I$309) -> 0 | AD17: =SUMIF(Woblink!E$14:E$314,A17,konwertery!R$2:R$300) -> 0 | AF17: =SUM(SUMIF(konwertery!I$2:I$300,A17,Azymut!H$2:H$298),(SUMIF(konwertery!S$2:S$300,A17,AzymutB!H$2:H313)*2)) -> 0 | AG17: =SUM(SUMIF(konwertery!I$2:I$300,A17,konwertery!J$2:J$300),SUMIF(konwertery!S$2:S$300,A17,konwertery!T$2:T$300)) -> 0 | AI17: =SUMIF(konwertery!K$2:K$300,A17,Ebookpoint!F$14:F$312) -> 0 | AJ17: =SUMIF(konwertery!K$2:K$300,A17,Ebookpoint!M$14:M$312) -> 0 | AL17: =SUMIF(konwertery!L$2:L$300,A17,Nasbi!F$14:F$312) -> 0 | AM17: =SUMIF(konwertery!L$2:L$300,A17,Nasbi!K$14:K$312) -> 0 | AO17: =SUMIF(StorytelE!C$2:C$300,A17,konwertery!M$2:M$300)+SUMIF(StorytelA!C$2:C$300,A17,konwertery!N$2:N$300) -> 0 | AP17: =SUMIF(StorytelE!C$2:C$300,A17,konwertery!O$2:O$300)+SUMIF(StorytelA!C$2:C$300,A17,konwertery!P$2:P$300) -> 0 | AR17: =SUMIF(konwertery!U$2:U$300,A17,Audioteka!E$4:E$302) -> 0 | AS17: =SUMIF(konwertery!U$2:U$300,A17,Audioteka!O$4:O$302) -> 0 | AU17: =SUMIF(Bookbeat!A$9:A$309,A17,Bookbeat!H$9:H$309) -> 0 | AV17: =SUMIF(Bookbeat!A$9:A$309,A17,Bookbeat!L$9:L$309) -> 0
A18: 9788365156280 | B18: Gdy Polacy nosili dredy, Kołtun – historia prawdziwa | E18: =H18+K18 -> 4 | F18: =I18+L18 -> 15.7521 | H18: =SUMIF(konwertery!A$2:A$300,A18,Histmag!C$2:C$300) -> 1 | I18: =SUMIF(konwertery!A$2:A$300,A18,konwertery!B$2:B$300) * 0.97 -> 7.6921 | K18: =N18+Q18+T18+W18+Z18+AC18+AF18+AI18+AL18+AO18+AR18+AU18 -> 3 | L18: =O18+R18+U18+X18+AA18+AD18+AG18+AJ18+AM18+AP18+AS18+AV18 -> 8.06 | N18: =SUMIF(konwertery!C$2:C$300,A18,Virtualo!L$2:L$300) -> 0 | O18: =(SUMIF(konwertery!C$2:C$300,A18,Virtualo!P$2:P$300)) -> 0 | Q18: =SUMIF(konwertery!D$2:D$300,A18,Empik!M$2:M$300) -> 0 | R18: =SUMIF(konwertery!D$2:D$300,A18,Empik!N$2:N$300) -> 0 | T18: =SUMIF(konwertery!E$2:E$300,A18,Publio!P$2:P$300) -> 0 | U18: =SUMIF(konwertery!E$2:E$300,A18,konwertery!F$2:F$300) -> 0 | W18: =SUMIF(Legimi!D$2:D$300,A18,Legimi!G$2:G$300) -> 0 | X18: =SUMIF(Legimi!D$2:D$300,A18,Legimi!H$2:H$300) -> 0 | Z18: =SUMIF(konwertery!G$2:G$302,A18,Nexto!J$2:J$283) -> 1 | AA18: =SUMIF(konwertery!G$2:G$302,A18,Nexto!N$2:P$302) -> 4.97 | AC18: =SUMIF(Woblink!E$9:E$309,A18,Woblink!I$9:I$309) -> 0 | AD18: =SUMIF(Woblink!E$14:E$314,A18,konwertery!R$2:R$300) -> 0 | AF18: =SUM(SUMIF(konwertery!I$2:I$300,A18,Azymut!H$2:H$298),(SUMIF(konwertery!S$2:S$300,A18,AzymutB!H$2:H314)*2)) -> 0 | AG18: =SUM(SUMIF(konwertery!I$2:I$300,A18,konwertery!J$2:J$300),SUMIF(konwertery!S$2:S$300,A18,konwertery!T$2:T$300)) -> 0 | AI18: =SUMIF(konwertery!K$2:K$300,A18,Ebookpoint!F$14:F$312) -> 0 | AJ18: =SUMIF(konwertery!K$2:K$300,A18,Ebookpoint!M$14:M$312) -> 0 | AL18: =SUMIF(konwertery!L$2:L$300,A18,Nasbi!F$14:F$312) -> 0 | AM18: =SUMIF(konwertery!L$2:L$300,A18,Nasbi!K$14:K$312) -> 0 | AO18: =SUMIF(StorytelE!C$2:C$300,A18,konwertery!M$2:M$300)+SUMIF(StorytelA!C$2:C$300,A18,konwertery!N$2:N$300) -> 2 | AP18: =SUMIF(StorytelE!C$2:C$300,A18,konwertery!O$2:O$300)+SUMIF(StorytelA!C$2:C$300,A18,konwertery!P$2:P$300) -> 3.09 | AR18: =SUMIF(konwertery!U$2:U$300,A18,Audioteka!E$4:E$302) -> 0 | AS18: =SUMIF(konwertery!U$2:U$300,A18,Audioteka!O$4:O$302) -> 0 | AU18: =SUMIF(Bookbeat!A$9:A$309,A18,Bookbeat!H$9:H$309) -> 0 | AV18: =SUMIF(Bookbeat!A$9:A$309,A18,Bookbeat!L$9:L$309) -> 0
A19: 9788365156761 | B19: Gdy Polacy nosili dredy, Kołtun – historia prawdziwa (audio) | E19: =H19+K19 -> 50 | F19: =I19+L19 -> 120.91 | H19: =SUMIF(konwertery!A$2:A$300,A19,Histmag!C$2:C$300) -> 0 | I19: =SUMIF(konwertery!A$2:A$300,A19,konwertery!B$2:B$300) * 0.97 -> 0 | K19: =N19+Q19+T19+W19+Z19+AC19+AF19+AI19+AL19+AO19+AR19+AU19 -> 50 | L19: =O19+R19+U19+X19+AA19+AD19+AG19+AJ19+AM19+AP19+AS19+AV19 -> 120.91 | N19: =SUMIF(konwertery!C$2:C$300,A19,Virtualo!L$2:L$300) -> 0 | O19: =(SUMIF(konwertery!C$2:C$300,A19,Virtualo!P$2:P$300)) -> 0 | Q19: =SUMIF(konwertery!D$2:D$300,A19,Empik!M$2:M$300) -> 4 | R19: =SUMIF(konwertery!D$2:D$300,A19,Empik!N$2:N$300) -> 36 | T19: =SUMIF(konwertery!E$2:E$300,A19,Publio!P$2:P$300) -> 0 | U19: =SUMIF(konwertery!E$2:E$300,A19,konwertery!F$2:F$300) -> 0 | W19: =SUMIF(Legimi!D$2:D$300,A19,Legimi!G$2:G$300) -> 1 | X19: =SUMIF(Legimi!D$2:D$300,A19,Legimi!H$2:H$300) -> 9.93 | Z19: =SUMIF(konwertery!G$2:G$302,A19,Nexto!J$2:J$283) -> 0 | AA19: =SUMIF(konwertery!G$2:G$302,A19,Nexto!N$2:P$302) -> 0 | AC19: =SUMIF(Woblink!E$14:E$314,A19,Woblink!I$14:I$314) -> 0 | AD19: =SUMIF(Woblink!E$14:E$314,A19,konwertery!R$2:R$300) -> 0 | AF19: =SUM(SUMIF(konwertery!I$2:I$300,A19,Azymut!H$2:H$298),(SUMIF(konwertery!S$2:S$300,A19,AzymutB!H$2:H315)*2)) -> 0 | AG19: =SUM(SUMIF(konwertery!I$2:I$300,A19,konwertery!J$2:J$300),SUMIF(konwertery!S$2:S$300,A19,konwertery!T$2:T$300)) -> 0 | AI19: =SUMIF(konwertery!K$2:K$300,A19,Ebookpoint!F$14:F$312) -> 0 | AJ19: =SUMIF(konwertery!K$2:K$300,A19,Ebookpoint!M$14:M$312) -> 0 | AL19: =SUMIF(konwertery!L$2:L$300,A19,Nasbi!F$14:F$312) -> 0 | AM19: =SUMIF(konwertery!L$2:L$300,A19,Nasbi!K$14:K$312) -> 0 | AO19: =SUMIF(StorytelE!C$2:C$300,A19,konwertery!M$2:M$300)+SUMIF(StorytelA!C$2:C$300,A19,konwertery!N$2:N$300) -> 43 | AP19: =SUMIF(StorytelE!C$2:C$300,A19,konwertery!O$2:O$300)+SUMIF(StorytelA!C$2:C$300,A19,konwertery!P$2:P$300) -> 57.96 | AR19: =SUMIF(konwertery!U$2:U$300,A19,Audioteka!E$4:E$302) -> 2 | AS19: =SUMIF(konwertery!U$2:U$300,A19,Audioteka!O$4:O$302) -> 17.02 | AU19: =SUMIF(Bookbeat!A$9:A$309,A19,Bookbeat!H$9:H$309) -> 0 | AV19: =SUMIF(Bookbeat!A$9:A$309,A19,Bookbeat!L$9:L$309) -> 0
A20: 9788365156464 | B20: Gdzie diabeł nie może, Morderczynie i filutki | E20: =H20+K20 -> 1 | F20: =I20+L20 -> 7 | H20: =SUMIF(konwertery!A$2:A$300,A20,Histmag!C$2:C$300) -> 0 | I20: =SUMIF(konwertery!A$2:A$300,A20,konwertery!B$2:B$300) * 0.97 -> 0 | K20: =N20+Q20+T20+W20+Z20+AC20+AF20+AI20+AL20+AO20+AR20+AU20 -> 1 | L20: =O20+R20+U20+X20+AA20+AD20+AG20+AJ20+AM20+AP20+AS20+AV20 -> 7 | N20: =SUMIF(konwertery!C$2:C$300,A20,Virtualo!L$2:L$300) -> 0 | O20: =(SUMIF(konwertery!C$2:C$300,A20,Virtualo!P$2:P$300)) -> 0 | Q20: =SUMIF(konwertery!D$2:D$300,A20,Empik!M$2:M$300) -> 1 | R20: =SUMIF(konwertery!D$2:D$300,A20,Empik!N$2:N$300) -> 7 | T20: =SUMIF(konwertery!E$2:E$300,A20,Publio!P$2:P$300) -> 0 | U20: =SUMIF(konwertery!E$2:E$300,A20,konwertery!F$2:F$300) -> 0 | W20: =SUMIF(Legimi!D$2:D$300,A20,Legimi!G$2:G$300) -> 0 | X20: =SUMIF(Legimi!D$2:D$300,A20,Legimi!H$2:H$300) -> 0 | Z20: =SUMIF(konwertery!G$2:G$302,A20,Nexto!J$2:J$283) -> 0 | AA20: =SUMIF(konwertery!G$2:G$302,A20,Nexto!N$2:P$302) -> 0 | AC20: =SUMIF(Woblink!E$9:E$309,A20,Woblink!I$9:I$309) -> 0 | AD20: =SUMIF(Woblink!E$14:E$314,A20,konwertery!R$2:R$300) -> 0 | AF20: =SUM(SUMIF(konwertery!I$2:I$300,A20,Azymut!H$2:H$298),(SUMIF(konwertery!S$2:S$300,A20,AzymutB!H$2:H316)*2)) -> 0 | AG20: =SUM(SUMIF(konwertery!I$2:I$300,A20,konwertery!J$2:J$300),SUMIF(konwertery!S$2:S$300,A20,konwertery!T$2:T$300)) -> 0 | AI20: =SUMIF(konwertery!K$2:K$300,A20,Ebookpoint!F$14:F$312) -> 0 | AJ20: =SUMIF(konwertery!K$2:K$300,A20,Ebookpoint!M$14:M$312) -> 0 | AL20: =SUMIF(konwertery!L$2:L$300,A20,Nasbi!F$14:F$312) -> 0 | AM20: =SUMIF(konwertery!L$2:L$300,A20,Nasbi!K$14:K$312) -> 0 | AO20: =SUMIF(StorytelE!C$2:C$300,A20,konwertery!M$2:M$300)+SUMIF(StorytelA!C$2:C$300,A20,konwertery!N$2:N$300) -> 0 | AP20: =SUMIF(StorytelE!C$2:C$300,A20,konwertery!O$2:O$300)+SUMIF(StorytelA!C$2:C$300,A20,konwertery!P$2:P$300) -> 0 | AR20: =SUMIF(konwertery!U$2:U$300,A20,Audioteka!E$4:E$302) -> 0 | AS20: =SUMIF(konwertery!U$2:U$300,A20,Audioteka!O$4:O$302) -> 0 | AU20: =SUMIF(Bookbeat!A$9:A$309,A20,Bookbeat!H$9:H$309) -> 0 | AV20: =SUMIF(Bookbeat!A$9:A$309,A20,Bookbeat!L$9:L$309) -> 0
A21: 9788365156242 | B21: Geniusze, nowatorzy i skandaliści polskiej literatury, Od Przybyszewskiego do Gombrowicza | E21: =H21+K21 -> 2 | F21: =I21+L21 -> 12.3601 | H21: =SUMIF(konwertery!A$2:A$300,A21,Histmag!C$2:C$300) -> 1 | I21: =SUMIF(konwertery!A$2:A$300,A21,konwertery!B$2:B$300) * 0.97 -> 10.9901 | K21: =N21+Q21+T21+W21+Z21+AC21+AF21+AI21+AL21+AO21+AR21+AU21 -> 1 | L21: =O21+R21+U21+X21+AA21+AD21+AG21+AJ21+AM21+AP21+AS21+AV21 -> 1.37 | N21: =SUMIF(konwertery!C$2:C$300,A21,Virtualo!L$2:L$300) -> 0 | O21: =(SUMIF(konwertery!C$2:C$300,A21,Virtualo!P$2:P$300)) -> 0 | Q21: =SUMIF(konwertery!D$2:D$300,A21,Empik!M$2:M$300) -> 0 | R21: =SUMIF(konwertery!D$2:D$300,A21,Empik!N$2:N$300) -> 0 | T21: =SUMIF(konwertery!E$2:E$300,A21,Publio!P$2:P$300) -> 0 | U21: =SUMIF(konwertery!E$2:E$300,A21,konwertery!F$2:F$300) -> 0 | W21: =SUMIF(Legimi!D$2:D$300,A21,Legimi!G$2:G$300) -> 0 | X21: =SUMIF(Legimi!D$2:D$300,A21,Legimi!H$2:H$300) -> 0 | Z21: =SUMIF(konwertery!G$2:G$302,A21,Nexto!J$2:J$283) -> 0 | AA21: =SUMIF(konwertery!G$2:G$302,A21,Nexto!N$2:P$302) -> 0 | AC21: =SUMIF(Woblink!E$9:E$309,A21,Woblink!I$9:I$309) -> 0 | AD21: =SUMIF(Woblink!E$14:E$314,A21,konwertery!R$2:R$300) -> 0 | AF21: =SUM(SUMIF(konwertery!I$2:I$300,A21,Azymut!H$2:H$298),(SUMIF(konwertery!S$2:S$300,A21,AzymutB!H$2:H317)*2)) -> 0 | AG21: =SUM(SUMIF(konwertery!I$2:I$300,A21,konwertery!J$2:J$300),SUMIF(konwertery!S$2:S$300,A21,konwertery!T$2:T$300)) -> 0 | AI21: =SUMIF(konwertery!K$2:K$300,A21,Ebookpoint!F$14:F$312) -> 0 | AJ21: =SUMIF(konwertery!K$2:K$300,A21,Ebookpoint!M$14:M$312) -> 0 | AL21: =SUMIF(konwertery!L$2:L$300,A21,Nasbi!F$14:F$312) -> 0 | AM21: =SUMIF(konwertery!L$2:L$300,A21,Nasbi!K$14:K$312) -> 0 | AO21: =SUMIF(StorytelE!C$2:C$300,A21,konwertery!M$2:M$300)+SUMIF(StorytelA!C$2:C$300,A21,konwertery!N$2:N$300) -> 1 | AP21: =SUMIF(StorytelE!C$2:C$300,A21,konwertery!O$2:O$300)+SUMIF(StorytelA!C$2:C$300,A21,konwertery!P$2:P$300) -> 1.37 | AR21: =SUMIF(konwertery!U$2:U$300,A21,Audioteka!E$4:E$302) -> 0 | AS21: =SUMIF(konwertery!U$2:U$300,A21,Audioteka!O$4:O$302) -> 0 | AU21: =SUMIF(Bookbeat!A$9:A$309,A21,Bookbeat!H$9:H$309) -> 0 | AV21: =SUMIF(Bookbeat!A$9:A$309,A21,Bookbeat!L$9:L$309) -> 0
A22: 9788365156716 | B22: Geniusze, nowatorzy i skandaliści polskiej literatury, Od Przybyszewskiego do Gombrowicza (audio) | E22: =H22+K22 -> 68 | F22: =I22+L22 -> 229.32 | H22: =SUMIF(konwertery!A$2:A$300,A22,Histmag!C$2:C$300) -> 0 | I22: =SUMIF(konwertery!A$2:A$300,A22,konwertery!B$2:B$300) * 0.97 -> 0 | K22: =N22+Q22+T22+W22+Z22+AC22+AF22+AI22+AL22+AO22+AR22+AU22 -> 68 | L22: =O22+R22+U22+X22+AA22+AD22+AG22+AJ22+AM22+AP22+AS22+AV22 -> 229.32 | N22: =SUMIF(konwertery!C$2:C$300,A22,Virtualo!L$2:L$300) -> 3 | O22: =(SUMIF(konwertery!C$2:C$300,A22,Virtualo!P$2:P$300)) -> 27.66 | Q22: =SUMIF(konwertery!D$2:D$300,A22,Empik!M$2:M$300) -> 7 | R22: =SUMIF(konwertery!D$2:D$300,A22,Empik!N$2:N$300) -> 51 | T22: =SUMIF(konwertery!E$2:E$300,A22,Publio!P$2:P$300) -> 0 | U22: =SUMIF(konwertery!E$2:E$300,A22,konwertery!F$2:F$300) -> 0 | W22: =SUMIF(Legimi!D$2:D$300,A22,Legimi!G$2:G$300) -> 1 | X22: =SUMIF(Legimi!D$2:D$300,A22,Legimi!H$2:H$300) -> 9.93 | Z22: =SUMIF(konwertery!G$2:G$302,A22,Nexto!J$2:J$283) -> 0 | AA22: =SUMIF(konwertery!G$2:G$302,A22,Nexto!N$2:P$302) -> 0 | AC22: =SUMIF(Woblink!E$9:E$309,A22,Woblink!I$9:I$309) -> 1 | AD22: =SUMIF(Woblink!E$14:E$314,A22,konwertery!R$2:R$300) -> 8.51 | AF22: =SUM(SUMIF(konwertery!I$2:I$300,A22,Azymut!H$2:H$298),(SUMIF(konwertery!S$2:S$300,A22,AzymutB!H$2:H318)*2)) -> 0 | AG22: =SUM(SUMIF(konwertery!I$2:I$300,A22,konwertery!J$2:J$300),SUMIF(konwertery!S$2:S$300,A22,konwertery!T$2:T$300)) -> 0 | AI22: =SUMIF(konwertery!K$2:K$300,A22,Ebookpoint!F$14:F$312) -> 1 | AJ22: =SUMIF(konwertery!K$2:K$300,A22,Ebookpoint!M$14:M$312) -> 9.08 | AL22: =SUMIF(konwertery!L$2:L$300,A22,Nasbi!F$14:F$312) -> 0 | AM22: =SUMIF(konwertery!L$2:L$300,A22,Nasbi!K$14:K$312) -> 0 | AO22: =SUMIF(StorytelE!C$2:C$300,A22,konwertery!M$2:M$300)+SUMIF(StorytelA!C$2:C$300,A22,konwertery!N$2:N$300) -> 42 | AP22: =SUMIF(StorytelE!C$2:C$300,A22,konwertery!O$2:O$300)+SUMIF(StorytelA!C$2:C$300,A22,konwertery!P$2:P$300) -> 57.45 | AR22: =SUMIF(konwertery!U$2:U$300,A22,Audioteka!E$4:E$302) -> 6 | AS22: =SUMIF(konwertery!U$2:U$300,A22,Audioteka!O$4:O$302) -> 51.06 | AU22: =SUMIF(Bookbeat!A$9:A$309,A22,Bookbeat!H$9:H$309) -> 7 | AV22: =SUMIF(Bookbeat!A$9:A$309,A22,Bookbeat!L$9:L$309) -> 14.63
A23: 9788393463039 | B23: Gorące lata trzydzieste, Wydarzenia, które wstrząsnęły Rzeczpospolitą | E23: =H23+K23 -> 3 | F23: =I23+L23 -> 19.3418 | H23: =SUMIF(konwertery!A$2:A$300,A23,Histmag!C$2:C$300) -> 3 | I23: =SUMIF(konwertery!A$2:A$300,A23,konwertery!B$2:B$300) * 0.97 -> 19.3418 | K23: =N23+Q23+T23+W23+Z23+AC23+AF23+AI23+AL23+AO23+AR23+AU23 -> 0 | L23: =O23+R23+U23+X23+AA23+AD23+AG23+AJ23+AM23+AP23+AS23+AV23 -> 0 | N23: =SUMIF(konwertery!C$2:C$300,A23,Virtualo!L$2:L$300) -> 0 | O23: =(SUMIF(konwertery!C$2:C$300,A23,Virtualo!P$2:P$300)) -> 0 | Q23: =SUMIF(konwertery!D$2:D$300,A23,Empik!M$2:M$300) -> 0 | R23: =SUMIF(konwertery!D$2:D$300,A23,Empik!N$2:N$300) -> 0 | T23: =SUMIF(konwertery!E$2:E$300,A23,Publio!P$2:P$300) -> 0 | U23: =SUMIF(konwertery!E$2:E$300,A23,konwertery!F$2:F$300) -> 0 | W23: =SUMIF(Legimi!D$2:D$300,A23,Legimi!G$2:G$300) -> 0 | X23: =SUMIF(Legimi!D$2:D$300,A23,Legimi!H$2:H$300) -> 0 | Z23: =SUMIF(konwertery!G$2:G$302,A23,Nexto!J$2:J$283) -> 0 | AA23: =SUMIF(konwertery!G$2:G$302,A23,Nexto!N$2:P$302) -> 0 | AC23: =SUMIF(Woblink!E$9:E$309,A23,Woblink!I$9:I$309) -> 0 | AD23: =SUMIF(Woblink!E$14:E$314,A23,konwertery!R$2:R$300) -> 0 | AF23: =SUM(SUMIF(konwertery!I$2:I$300,A23,Azymut!H$2:H$298),(SUMIF(konwertery!S$2:S$300,A23,AzymutB!H$2:H319)*2)) -> 0 | AG23: =SUM(SUMIF(konwertery!I$2:I$300,A23,konwertery!J$2:J$300),SUMIF(konwertery!S$2:S$300,A23,konwertery!T$2:T$300)) -> 0 | AI23: =SUMIF(konwertery!K$2:K$300,A23,Ebookpoint!F$14:F$312) -> 0 | AJ23: =SUMIF(konwertery!K$2:K$300,A23,Ebookpoint!M$14:M$312) -> 0 | AL23: =SUMIF(konwertery!L$2:L$300,A23,Nasbi!F$14:F$312) -> 0 | AM23: =SUMIF(konwertery!L$2:L$300,A23,Nasbi!K$14:K$312) -> 0 | AO23: =SUMIF(StorytelE!C$2:C$300,A23,konwertery!M$2:M$300)+SUMIF(StorytelA!C$2:C$300,A23,konwertery!N$2:N$300) -> 0 | AP23: =SUMIF(StorytelE!C$2:C$300,A23,konwertery!O$2:O$300)+SUMIF(StorytelA!C$2:C$300,A23,konwertery!P$2:P$300) -> 0 | AR23: =SUMIF(konwertery!U$2:U$300,A23,Audioteka!E$4:E$302) -> 0 | AS23: =SUMIF(konwertery!U$2:U$300,A23,Audioteka!O$4:O$302) -> 0 | AU23: =SUMIF(Bookbeat!A$9:A$309,A23,Bookbeat!H$9:H$309) -> 0 | AV23: =SUMIF(Bookbeat!A$9:A$309,A23,Bookbeat!L$9:L$309) -> 0
A24: 9788365156457 | B24: Gorące lata trzydzieste, Wydarzenia, które wstrząsnęły Rzeczpospolitą (audio) | E24: =H24+K24 -> 41 | F24: =I24+L24 -> 75.3544 | H24: =SUMIF(konwertery!A$2:A$300,A24,Histmag!C$2:C$300) -> 1 | I24: =SUMIF(konwertery!A$2:A$300,A24,konwertery!B$2:B$300) * 0.97 -> 7.2944 | K24: =N24+Q24+T24+W24+Z24+AC24+AF24+AI24+AL24+AO24+AR24+AU24 -> 40 | L24: =O24+R24+U24+X24+AA24+AD24+AG24+AJ24+AM24+AP24+AS24+AV24 -> 68.06 | N24: =SUMIF(konwertery!C$2:C$300,A24,Virtualo!L$2:L$300) -> 0 | O24: =(SUMIF(konwertery!C$2:C$300,A24,Virtualo!P$2:P$300)) -> 0 | Q24: =SUMIF(konwertery!D$2:D$300,A24,Empik!M$2:M$300) -> 3 | R24: =SUMIF(konwertery!D$2:D$300,A24,Empik!N$2:N$300) -> 19 | T24: =SUMIF(konwertery!E$2:E$300,A24,Publio!P$2:P$300) -> 0 | U24: =SUMIF(konwertery!E$2:E$300,A24,konwertery!F$2:F$300) -> 0 | W24: =SUMIF(Legimi!D$2:D$300,A24,Legimi!G$2:G$300) -> 1 | X24: =SUMIF(Legimi!D$2:D$300,A24,Legimi!H$2:H$300) -> 7.27 | Z24: =SUMIF(konwertery!G$2:G$302,A24,Nexto!J$2:J$283) -> 0 | AA24: =SUMIF(konwertery!G$2:G$302,A24,Nexto!N$2:P$302) -> 0 | AC24: =SUMIF(Woblink!E$9:E$309,A24,Woblink!I$9:I$309) -> 0 | AD24: =SUMIF(Woblink!E$14:E$314,A24,konwertery!R$2:R$300) -> 0 | AF24: =SUM(SUMIF(konwertery!I$2:I$300,A24,Azymut!H$2:H$298),(SUMIF(konwertery!S$2:S$300,A24,AzymutB!H$2:H320)*2)) -> 0 | AG24: =SUM(SUMIF(konwertery!I$2:I$300,A24,konwertery!J$2:J$300),SUMIF(konwertery!S$2:S$300,A24,konwertery!T$2:T$300)) -> 0 | AI24: =SUMIF(konwertery!K$2:K$300,A24,Ebookpoint!F$14:F$312) -> 0 | AJ24: =SUMIF(konwertery!K$2:K$300,A24,Ebookpoint!M$14:M$312) -> 0 | AL24: =SUMIF(konwertery!L$2:L$300,A24,Nasbi!F$14:F$312) -> 0 | AM24: =SUMIF(konwertery!L$2:L$300,A24,Nasbi!K$14:K$312) -> 0 | AO24: =SUMIF(StorytelE!C$2:C$300,A24,konwertery!M$2:M$300)+SUMIF(StorytelA!C$2:C$300,A24,konwertery!N$2:N$300) -> 35 | AP24: =SUMIF(StorytelE!C$2:C$300,A24,konwertery!O$2:O$300)+SUMIF(StorytelA!C$2:C$300,A24,konwertery!P$2:P$300) -> 35.56 | AR24: =SUMIF(konwertery!U$2:U$300,A24,Audioteka!E$4:E$302) -> 1 | AS24: =SUMIF(konwertery!U$2:U$300,A24,Audioteka!O$4:O$302) -> 6.23 | AU24: =SUMIF(Bookbeat!A$9:A$309,A24,Bookbeat!H$9:H$309) -> 0 | AV24: =SUMIF(Bookbeat!A$9:A$309,A24,Bookbeat!L$9:L$309) -> 0
A25: 9788365156105 | B25: Henryk Sienkiewicz jakiego nie znamy | E25: =H25+K25 -> 0 | F25: =I25+L25 -> 0 | H25: =SUMIF(konwertery!A$2:A$300,A25,Histmag!C$2:C$300) -> 0 | I25: =SUMIF(konwertery!A$2:A$300,A25,konwertery!B$2:B$300) * 0.97 -> 0 | K25: =N25+Q25+T25+W25+Z25+AC25+AF25+AI25+AL25+AO25+AR25+AU25 -> 0 | L25: =O25+R25+U25+X25+AA25+AD25+AG25+AJ25+AM25+AP25+AS25+AV25 -> 0 | N25: =SUMIF(konwertery!C$2:C$300,A25,Virtualo!L$2:L$300) -> 0 | O25: =(SUMIF(konwertery!C$2:C$300,A25,Virtualo!P$2:P$300)) -> 0 | Q25: =SUMIF(konwertery!D$2:D$300,A25,Empik!M$2:M$300) -> 0 | R25: =SUMIF(konwertery!D$2:D$300,A25,Empik!N$2:N$300) -> 0 | T25: =SUMIF(konwertery!E$2:E$300,A25,Publio!P$2:P$300) -> 0 | U25: =SUMIF(konwertery!E$2:E$300,A25,konwertery!F$2:F$300) -> 0 | W25: =SUMIF(Legimi!D$2:D$300,A25,Legimi!G$2:G$300) -> 0 | X25: =SUMIF(Legimi!D$2:D$300,A25,Legimi!H$2:H$300) -> 0 | Z25: =SUMIF(konwertery!G$2:G$302,A25,Nexto!J$2:J$283) -> 0 | AA25: =SUMIF(konwertery!G$2:G$302,A25,Nexto!N$2:P$302) -> 0 | AC25: =SUMIF(Woblink!E$9:E$309,A25,Woblink!I$9:I$309) -> 0 | AD25: =SUMIF(Woblink!E$14:E$314,A25,konwertery!R$2:R$300) -> 0 | AF25: =SUM(SUMIF(konwertery!I$2:I$300,A25,Azymut!H$2:H$298),(SUMIF(konwertery!S$2:S$300,A25,AzymutB!H$2:H321)*2)) -> 0 | AG25: =SUM(SUMIF(konwertery!I$2:I$300,A25,konwertery!J$2:J$300),SUMIF(konwertery!S$2:S$300,A25,konwertery!T$2:T$300)) -> 0 | AI25: =SUMIF(konwertery!K$2:K$300,A25,Ebookpoint!F$14:F$312) -> 0 | AJ25: =SUMIF(konwertery!K$2:K$300,A25,Ebookpoint!M$14:M$312) -> 0 | AL25: =SUMIF(konwertery!L$2:L$300,A25,Nasbi!F$14:F$312) -> 0 | AM25: =SUMIF(konwertery!L$2:L$300,A25,Nasbi!K$14:K$312) -> 0 | AO25: =SUMIF(StorytelE!C$2:C$300,A25,konwertery!M$2:M$300)+SUMIF(StorytelA!C$2:C$300,A25,konwertery!N$2:N$300) -> 0 | AP25: =SUMIF(StorytelE!C$2:C$300,A25,konwertery!O$2:O$300)+SUMIF(StorytelA!C$2:C$300,A25,konwertery!P$2:P$300) -> 0 | AR25: =SUMIF(konwertery!U$2:U$300,A25,Audioteka!E$4:E$302) -> 0 | AS25: =SUMIF(konwertery!U$2:U$300,A25,Audioteka!O$4:O$302) -> 0 | AU25: =SUMIF(Bookbeat!A$9:A$309,A25,Bookbeat!H$9:H$309) -> 0 | AV25: =SUMIF(Bookbeat!A$9:A$309,A25,Bookbeat!L$9:L$309) -> 0
A26: 9788365156587 | B26: Hetmani i dowódcy I Rzeczpospolitej | E26: =H26+K26 -> 2 | F26: =I26+L26 -> 17.8868 | H26: =SUMIF(konwertery!A$2:A$300,A26,Histmag!C$2:C$300) -> 2 | I26: =SUMIF(konwertery!A$2:A$300,A26,konwertery!B$2:B$300) * 0.97 -> 17.8868 | K26: =N26+Q26+T26+W26+Z26+AC26+AF26+AI26+AL26+AO26+AR26+AU26 -> 0 | L26: =O26+R26+U26+X26+AA26+AD26+AG26+AJ26+AM26+AP26+AS26+AV26 -> 0 | N26: =SUMIF(konwertery!C$2:C$300,A26,Virtualo!L$2:L$300) -> 0 | O26: =(SUMIF(konwertery!C$2:C$300,A26,Virtualo!P$2:P$300)) -> 0 | Q26: =SUMIF(konwertery!D$2:D$300,A26,Empik!M$2:M$300) -> 0 | R26: =SUMIF(konwertery!D$2:D$300,A26,Empik!N$2:N$300) -> 0 | T26: =SUMIF(konwertery!E$2:E$300,A26,Publio!P$2:P$300) -> 0 | U26: =SUMIF(konwertery!E$2:E$300,A26,konwertery!F$2:F$300) -> 0 | W26: =SUMIF(Legimi!D$2:D$300,A26,Legimi!G$2:G$300) -> 0 | X26: =SUMIF(Legimi!D$2:D$300,A26,Legimi!H$2:H$300) -> 0 | Z26: =SUMIF(konwertery!G$2:G$302,A26,Nexto!J$2:J$283) -> 0 | AA26: =SUMIF(konwertery!G$2:G$302,A26,Nexto!N$2:P$302) -> 0 | AC26: =SUMIF(Woblink!E$9:E$309,A26,Woblink!I$9:I$309) -> 0 | AD26: =SUMIF(Woblink!E$14:E$314,A26,konwertery!R$2:R$300) -> 0 | AF26: =SUM(SUMIF(konwertery!I$2:I$300,A26,Azymut!H$2:H$298),(SUMIF(konwertery!S$2:S$300,A26,AzymutB!H$2:H322)*2)) -> 0 | AG26: =SUM(SUMIF(konwertery!I$2:I$300,A26,konwertery!J$2:J$300),SUMIF(konwertery!S$2:S$300,A26,konwertery!T$2:T$300)) -> 0 | AI26: =SUMIF(konwertery!K$2:K$300,A26,Ebookpoint!F$14:F$312) -> 0 | AJ26: =SUMIF(konwertery!K$2:K$300,A26,Ebookpoint!M$14:M$312) -> 0 | AL26: =SUMIF(konwertery!L$2:L$300,A26,Nasbi!F$14:F$312) -> 0 | AM26: =SUMIF(konwertery!L$2:L$300,A26,Nasbi!K$14:K$312) -> 0 | AO26: =SUMIF(StorytelE!C$2:C$300,A26,konwertery!M$2:M$300)+SUMIF(StorytelA!C$2:C$300,A26,konwertery!N$2:N$300) -> 0 | AP26: =SUMIF(StorytelE!C$2:C$300,A26,konwertery!O$2:O$300)+SUMIF(StorytelA!C$2:C$300,A26,konwertery!P$2:P$300) -> 0 | AR26: =SUMIF(konwertery!U$2:U$300,A26,Audioteka!E$4:E$302) -> 0 | AS26: =SUMIF(konwertery!U$2:U$300,A26,Audioteka!O$4:O$302) -> 0 | AU26: =SUMIF(Bookbeat!A$9:A$309,A26,Bookbeat!H$9:H$309) -> 0 | AV26: =SUMIF(Bookbeat!A$9:A$309,A26,Bookbeat!L$9:L$309) -> 0
A27: 9788365156549 | B27: Hetmani i dowódcy I Rzeczpospolitej, Część II | E27: =H27+K27 -> 3 | F27: =I27+L27 -> 27.5189 | H27: =SUMIF(konwertery!A$2:A$300,A27,Histmag!C$2:C$300) -> 3 | I27: =SUMIF(konwertery!A$2:A$300,A27,konwertery!B$2:B$300) * 0.97 -> 27.5189 | K27: =N27+Q27+T27+W27+Z27+AC27+AF27+AI27+AL27+AO27+AR27+AU27 -> 0 | L27: =O27+R27+U27+X27+AA27+AD27+AG27+AJ27+AM27+AP27+AS27+AV27 -> 0 | N27: =SUMIF(konwertery!C$2:C$300,A27,Virtualo!L$2:L$300) -> 0 | O27: =(SUMIF(konwertery!C$2:C$300,A27,Virtualo!P$2:P$300)) -> 0 | Q27: =SUMIF(konwertery!D$2:D$300,A27,Empik!M$2:M$300) -> 0 | R27: =SUMIF(konwertery!D$2:D$300,A27,Empik!N$2:N$300) -> 0 | T27: =SUMIF(konwertery!E$2:E$300,A27,Publio!P$2:P$300) -> 0 | U27: =SUMIF(konwertery!E$2:E$300,A27,konwertery!F$2:F$300) -> 0 | W27: =SUMIF(Legimi!D$2:D$300,A27,Legimi!G$2:G$300) -> 0 | X27: =SUMIF(Legimi!D$2:D$300,A27,Legimi!H$2:H$300) -> 0 | Z27: =SUMIF(konwertery!G$2:G$302,A27,Nexto!J$2:J$283) -> 0 | AA27: =SUMIF(konwertery!G$2:G$302,A27,Nexto!N$2:P$302) -> 0 | AC27: =SUMIF(Woblink!E$9:E$309,A27,Woblink!I$9:I$309) -> 0 | AD27: =SUMIF(Woblink!E$14:E$314,A27,konwertery!R$2:R$300) -> 0 | AF27: =SUM(SUMIF(konwertery!I$2:I$300,A27,Azymut!H$2:H$298),(SUMIF(konwertery!S$2:S$300,A27,AzymutB!H$2:H323)*2)) -> 0 | AG27: =SUM(SUMIF(konwertery!I$2:I$300,A27,konwertery!J$2:J$300),SUMIF(konwertery!S$2:S$300,A27,konwertery!T$2:T$300)) -> 0 | AI27: =SUMIF(konwertery!K$2:K$300,A27,Ebookpoint!F$14:F$312) -> 0 | AJ27: =SUMIF(konwertery!K$2:K$300,A27,Ebookpoint!M$14:M$312) -> 0 | AL27: =SUMIF(konwertery!L$2:L$300,A27,Nasbi!F$14:F$312) -> 0 | AM27: =SUMIF(konwertery!L$2:L$300,A27,Nasbi!K$14:K$312) -> 0 | AO27: =SUMIF(StorytelE!C$2:C$300,A27,konwertery!M$2:M$300)+SUMIF(StorytelA!C$2:C$300,A27,konwertery!N$2:N$300) -> 0 | AP27: =SUMIF(StorytelE!C$2:C$300,A27,konwertery!O$2:O$300)+SUMIF(StorytelA!C$2:C$300,A27,konwertery!P$2:P$300) -> 0 | AR27: =SUMIF(konwertery!U$2:U$300,A27,Audioteka!E$4:E$302) -> 0 | AS27: =SUMIF(konwertery!U$2:U$300,A27,Audioteka!O$4:O$302) -> 0 | AU27: =SUMIF(Bookbeat!A$9:A$309,A27,Bookbeat!H$9:H$309) -> 0 | AV27: =SUMIF(Bookbeat!A$9:A$309,A27,Bookbeat!L$9:L$309) -> 0
A28: 9788365156310 | B28: Hetmani i dowódcy I Rzeczpospolitej, Część III | E28: =H28+K28 -> 5 | F28: =I28+L28 -> 38.5889 | H28: =SUMIF(konwertery!A$2:A$300,A28,Histmag!C$2:C$300) -> 3 | I28: =SUMIF(konwertery!A$2:A$300,A28,konwertery!B$2:B$300) * 0.97 -> 27.5189 | K28: =N28+Q28+T28+W28+Z28+AC28+AF28+AI28+AL28+AO28+AR28+AU28 -> 2 | L28: =O28+R28+U28+X28+AA28+AD28+AG28+AJ28+AM28+AP28+AS28+AV28 -> 11.07 | N28: =SUMIF(konwertery!C$2:C$300,A28,Virtualo!L$2:L$300) -> 0 | O28: =(SUMIF(konwertery!C$2:C$300,A28,Virtualo!P$2:P$300)) -> 0 | Q28: =SUMIF(konwertery!D$2:D$300,A28,Empik!M$2:M$300) -> 1 | R28: =SUMIF(konwertery!D$2:D$300,A28,Empik!N$2:N$300) -> 9 | T28: =SUMIF(konwertery!E$2:E$300,A28,Publio!P$2:P$300) -> 0 | U28: =SUMIF(konwertery!E$2:E$300,A28,konwertery!F$2:F$300) -> 0 | W28: =SUMIF(Legimi!D$2:D$300,A28,Legimi!G$2:G$300) -> 0 | X28: =SUMIF(Legimi!D$2:D$300,A28,Legimi!H$2:H$300) -> 0 | Z28: =SUMIF(konwertery!G$2:G$302,A28,Nexto!J$2:J$283) -> 0 | AA28: =SUMIF(konwertery!G$2:G$302,A28,Nexto!N$2:P$302) -> 0 | AC28: =SUMIF(Woblink!E$9:E$309,A28,Woblink!I$9:I$309) -> 0 | AD28: =SUMIF(Woblink!E$14:E$314,A28,konwertery!R$2:R$300) -> 0 | AF28: =SUM(SUMIF(konwertery!I$2:I$300,A28,Azymut!H$2:H$298),(SUMIF(konwertery!S$2:S$300,A28,AzymutB!H$2:H324)*2)) -> 0 | AG28: =SUM(SUMIF(konwertery!I$2:I$300,A28,konwertery!J$2:J$300),SUMIF(konwertery!S$2:S$300,A28,konwertery!T$2:T$300)) -> 0 | AI28: =SUMIF(konwertery!K$2:K$300,A28,Ebookpoint!F$14:F$312) -> 0 | AJ28: =SUMIF(konwertery!K$2:K$300,A28,Ebookpoint!M$14:M$312) -> 0 | AL28: =SUMIF(konwertery!L$2:L$300,A28,Nasbi!F$14:F$312) -> 0 | AM28: =SUMIF(konwertery!L$2:L$300,A28,Nasbi!K$14:K$312) -> 0 | AO28: =SUMIF(StorytelE!C$2:C$300,A28,konwertery!M$2:M$300)+SUMIF(StorytelA!C$2:C$300,A28,konwertery!N$2:N$300) -> 1 | AP28: =SUMIF(StorytelE!C$2:C$300,A28,konwertery!O$2:O$300)+SUMIF(StorytelA!C$2:C$300,A28,konwertery!P$2:P$300) -> 2.07 | AR28: =SUMIF(konwertery!U$2:U$300,A28,Audioteka!E$4:E$302) -> 0 | AS28: =SUMIF(konwertery!U$2:U$300,A28,Audioteka!O$4:O$302) -> 0 | AU28: =SUMIF(Bookbeat!A$9:A$309,A28,Bookbeat!H$9:H$309) -> 0 | AV28: =SUMIF(Bookbeat!A$9:A$309,A28,Bookbeat!L$9:L$309) -> 0
A29: 9788365156792 | B29: Hetmani i dowódcy I Rzeczpospolitej (audio) | E29: =H29+K29 -> 34 | F29: =I29+L29 -> 174.1834 | H29: =SUMIF(konwertery!A$2:A$300,A29,Histmag!C$2:C$300) -> 1 | I29: =SUMIF(konwertery!A$2:A$300,A29,konwertery!B$2:B$300) * 0.97 -> 8.9434 | K29: =N29+Q29+T29+W29+Z29+AC29+AF29+AI29+AL29+AO29+AR29+AU29 -> 33 | L29: =O29+R29+U29+X29+AA29+AD29+AG29+AJ29+AM29+AP29+AS29+AV29 -> 165.24 | N29: =SUMIF(konwertery!C$2:C$300,A29,Virtualo!L$2:L$300) -> 0 | O29: =(SUMIF(konwertery!C$2:C$300,A29,Virtualo!P$2:P$300)) -> 0 | Q29: =SUMIF(konwertery!D$2:D$300,A29,Empik!M$2:M$300) -> 4 | R29: =SUMIF(konwertery!D$2:D$300,A29,Empik!N$2:N$300) -> 32 | T29: =SUMIF(konwertery!E$2:E$300,A29,Publio!P$2:P$300) -> 0 | U29: =SUMIF(konwertery!E$2:E$300,A29,konwertery!F$2:F$300) -> 0 | W29: =SUMIF(Legimi!D$2:D$300,A29,Legimi!G$2:G$300) -> 1 | X29: =SUMIF(Legimi!D$2:D$300,A29,Legimi!H$2:H$300) -> 11.93 | Z29: =SUMIF(konwertery!G$2:G$302,A29,Nexto!J$2:J$283) -> 0 | AA29: =SUMIF(konwertery!G$2:G$302,A29,Nexto!N$2:P$302) -> 0 | AC29: =SUMIF(Woblink!E$9:E$309,A29,Woblink!I$9:I$309) -> 0 | AD29: =SUMIF(Woblink!E$14:E$314,A29,konwertery!R$2:R$300) -> 0 | AF29: =SUM(SUMIF(konwertery!I$2:I$300,A29,Azymut!H$2:H$298),(SUMIF(konwertery!S$2:S$300,A29,AzymutB!H$2:H325)*2)) -> 0 | AG29: =SUM(SUMIF(konwertery!I$2:I$300,A29,konwertery!J$2:J$300),SUMIF(konwertery!S$2:S$300,A29,konwertery!T$2:T$300)) -> 0 | AI29: =SUMIF(konwertery!K$2:K$300,A29,Ebookpoint!F$14:F$312) -> 0 | AJ29: =SUMIF(konwertery!K$2:K$300,A29,Ebookpoint!M$14:M$312) -> 0 | AL29: =SUMIF(konwertery!L$2:L$300,A29,Nasbi!F$14:F$312) -> 1 | AM29: =SUMIF(konwertery!L$2:L$300,A29,Nasbi!K$14:K$312) -> 10.91 | AO29: =SUMIF(StorytelE!C$2:C$300,A29,konwertery!M$2:M$300)+SUMIF(StorytelA!C$2:C$300,A29,konwertery!N$2:N$300) -> 21 | AP29: =SUMIF(StorytelE!C$2:C$300,A29,konwertery!O$2:O$300)+SUMIF(StorytelA!C$2:C$300,A29,konwertery!P$2:P$300) -> 50.3 | AR29: =SUMIF(konwertery!U$2:U$300,A29,Audioteka!E$4:E$302) -> 6 | AS29: =SUMIF(konwertery!U$2:U$300,A29,Audioteka!O$4:O$302) -> 60.1 | AU29: =SUMIF(Bookbeat!A$9:A$309,A29,Bookbeat!H$9:H$309) -> 0 | AV29: =SUMIF(Bookbeat!A$9:A$309,A29,Bookbeat!L$9:L$309) -> 0
A30: 9788362329984 | B30: Historia, Poradnik maturalny | E30: =H30+K30 -> 2 | F30: =I30+L30 -> 12.7458 | H30: =SUMIF(konwertery!A$2:A$300,A30,Histmag!C$2:C$300) -> 2 | I30: =SUMIF(konwertery!A$2:A$300,A30,konwertery!B$2:B$300) * 0.97 -> 12.7458 | K30: =N30+Q30+T30+W30+Z30+AC30+AF30+AI30+AL30+AO30+AR30+AU30 -> 0 | L30: =O30+R30+U30+X30+AA30+AD30+AG30+AJ30+AM30+AP30+AS30+AV30 -> 0 | N30: =SUMIF(konwertery!C$2:C$300,A30,Virtualo!L$2:L$300) -> 0 | O30: =(SUMIF(konwertery!C$2:C$300,A30,Virtualo!P$2:P$300)) -> 0 | Q30: =SUMIF(konwertery!D$2:D$300,A30,Empik!M$2:M$300) -> 0 | R30: =SUMIF(konwertery!D$2:D$300,A30,Empik!N$2:N$300) -> 0 | T30: =SUMIF(konwertery!E$2:E$300,A30,Publio!P$2:P$300) -> 0 | U30: =SUMIF(konwertery!E$2:E$300,A30,konwertery!F$2:F$300) -> 0 | W30: =SUMIF(Legimi!D$2:D$300,A30,Legimi!G$2:G$300) -> 0 | X30: =SUMIF(Legimi!D$2:D$300,A30,Legimi!H$2:H$300) -> 0 | Z30: =SUMIF(konwertery!G$2:G$302,A30,Nexto!J$2:J$283) -> 0 | AA30: =SUMIF(konwertery!G$2:G$302,A30,Nexto!N$2:P$302) -> 0 | AC30: =SUMIF(Woblink!E$9:E$309,A30,Woblink!I$9:I$309) -> 0 | AD30: =SUMIF(Woblink!E$14:E$314,A30,konwertery!R$2:R$300) -> 0 | AF30: =SUM(SUMIF(konwertery!I$2:I$300,A30,Azymut!H$2:H$298),(SUMIF(konwertery!S$2:S$300,A30,AzymutB!H$2:H326)*2)) -> 0 | AG30: =SUM(SUMIF(konwertery!I$2:I$300,A30,konwertery!J$2:J$300),SUMIF(konwertery!S$2:S$300,A30,konwertery!T$2:T$300)) -> 0 | AI30: =SUMIF(konwertery!K$2:K$300,A30,Ebookpoint!F$14:F$312) -> 0 | AJ30: =SUMIF(konwertery!K$2:K$300,A30,Ebookpoint!M$14:M$312) -> 0 | AL30: =SUMIF(konwertery!L$2:L$300,A30,Nasbi!F$14:F$312) -> 0 | AM30: =SUMIF(konwertery!L$2:L$300,A30,Nasbi!K$14:K$312) -> 0 | AO30: =SUMIF(StorytelE!C$2:C$300,A30,konwertery!M$2:M$300)+SUMIF(StorytelA!C$2:C$300,A30,konwertery!N$2:N$300) -> 0 | AP30: =SUMIF(StorytelE!C$2:C$300,A30,konwertery!O$2:O$300)+SUMIF(StorytelA!C$2:C$300,A30,konwertery!P$2:P$300) -> 0 | AR30: =SUMIF(konwertery!U$2:U$300,A30,Audioteka!E$4:E$302) -> 0 | AS30: =SUMIF(konwertery!U$2:U$300,A30,Audioteka!O$4:O$302) -> 0 | AU30: =SUMIF(Bookbeat!A$9:A$309,A30,Bookbeat!H$9:H$309) -> 0 | AV30: =SUMIF(Bookbeat!A$9:A$309,A30,Bookbeat!L$9:L$309) -> 0
